Workbook

Sheet Summ
H1: 45689 | AO1: 45717 | BY1: 45748 | DG1: Feb,Mar & Apr 2025 | DN1: 45778 | EX1: 45809 | GG1: 45839 | HQ1: May, Jun & Jul 2025
A2: Sl.No | B2: Name of Products | C2: Actual rate | D2: Sale price | E2: Comm(20%) | F2: Discount | H2: 1 | I2: 2 | J2: 3 | K2: 4 | L2: 5 | M2: 6 | N2: 7 | O2: 8 | P2: 9 | Q2: 10 | R2: 11 | S2: 12 | T2: 13 | U2: 14 | V2: 15 | W2: 16 | X2: 17 | Y2: 18 | Z2: 19 | AA2: 20 | AB2: 21 | AC2: 22 | AD2: 23 | AE2: 24 | AF2: 25 | AG2: 26 | AH2: 27 | AI2: 28 | AJ2: Total Qty | AK2: Total Amount | AL2: Total Comm | AM2: Total Payable | AO2: 1 | AP2: 2 | AQ2: 3 | AR2: 4 | AS2: 5 | AT2: 6 | AU2: 7 | AV2: 8 | AW2: 9 | AX2: 10 | AY2: 11 | AZ2: 12 | BA2: 13 | BB2: 14 | BC2: 15 | BD2: 16 | BE2: 17 | BF2: 18 | BG2: 19 | BH2: 20 | BI2: 21 | BJ2: 22 | BK2: 23 | BL2: 24 | BM2: 25 | BN2: 26 | BO2: 27 | BP2: 28 | BQ2: 29 | BR2: 30 | BS2: 31 | BT2: Total Qty | BU2: Total Amount | BV2: Total Comm | BW2: Total Payable | BY2: 1 | BZ2: 2 | CA2: 3 | CB2: 4 | CC2: 5 | CD2: 6 | CE2: 7 | CF2: 8 | CG2: 9 | CH2: 10 | CI2: 11 | CJ2: 12 | CK2: 13 | CL2: 14 | CM2: 15 | CN2: 16 | CO2: 17 | CP2: 18 | CQ2: 19 | CR2: 20 | CS2: 21 | CT2: 22 | CU2: 23 | CV2: 24 | CW2: 25 | CX2: 26 | CY2: 27 | CZ2: 28 | DA2: 29 | DB2: 30 | DC2: Total Qty | DD2: Total Amount | DE2: Total Comm | DF2: Total Payable | DG2: QTY of F,M&A | DH2: Actual rate | DI2: Sale price | DJ2: Comm(20%) | DK2: Discount | DL2: Amount | DN2: 1 | DO2: 2 | DP2: 3 | DQ2: 4 | DR2: 5 | DS2: 6 | DT2: 7 | DU2: 8 | DV2: 9 | DW2: 10 | DX2: 11 | DY2: 12 | DZ2: 13 | EA2: 14 | EB2: 15 | EC2: 16 | ED2: 17 | EE2: 18 | EF2: 19 | EG2: 20 | EH2: 21 | EI2: 22 | EJ2: 23 | EK2: 24 | EL2: 25 | EM2: 26 | EN2: 27 | EO2: 28 | EP2: 29 | EQ2: 30 | ER2: 31 | ES2: Total Qty | ET2: Total Amount | EU2: Total Comm | EV2: Total Payable | EX2: 1 | EY2: 2 | EZ2: 3 | FA2: 4 | FB2: 5 | FC2: 6 | FD2: 7 | FE2: 8 | FF2: 9 | FG2: 10 | FH2: 11 | FI2: 12 | FJ2: 13 | FK2: 14 | FL2: 15 | FM2: 16 | FN2: 17 | FO2: 18 | FP2: 19 | FQ2: 20 | FR2: 21 | FS2: 22 | FT2: 23 | FU2: 24 | FV2: 25 | FW2: 26 | FX2: 27 | FY2: 28 | FZ2: 29 | GA2: 30 | GB2: Total Qty | GC2: Total Amount | GD2: Total Comm | GE2: Total Payable | GG2: 1 | GH2: 2 | GI2: 3 | GJ2: 4 | GK2: 5 | GL2: 6 | GM2: 7 | GN2: 8 | GO2: 9 | GP2: 10 | GQ2: 11 | GR2: 12 | GS2: 13 | GT2: 14 | GU2: 15 | GV2: 16 | GW2: 17 | GX2: 18 | GY2: 19 | GZ2: 20 | HA2: 21 | HB2: 22 | HC2: 23 | HD2: 24 | HE2: 25 | HF2: 26 | HG2: 27 | HH2: 28 | HI2: 29 | HJ2: 30 | HK2: 31 | HL2: Total Qty | HM2: Total Amount | HN2: Total Comm | HO2: Total Payable | HQ2: QTY of M,J&J | HR2: Actual rate | HS2: Sale price | HT2: Comm(20%) | HU2: Discount | HV2: Amount | IN2: Total Qty | IO2: Total Amount | IP2: Total Comm | IQ2: Total Payable
A3: 1 | B3: Safflower and Cinamon Tea | C3: 300 | D3: 360 | E3: =D3-C3 -> 60 | F3: 10% Discount on every 80 boxes | I3: =PHLY!I3 -> 0 | J3: =PHLY!J3 -> 0 | K3: =PHLY!K3 -> 0 | L3: =PHLY!L3 -> 0 | M3: =PHLY!M3 -> 0 | N3: =PHLY!N3 -> 0 | O3: =PHLY!O3 -> 0 | P3: =PHLY!P3 -> 0 | ... AM3: =PHLY!AM3 -> 0 | AO3: =WANG!H3+PUNA!H3+GELA!H3+ZEMG!H3+TRON!H3+BUMA!H3+SARA!H3+TSIR!H3+DGNA!H3+PANG!H3+DPLA!H3+SJKA!H3+LUNT!H3+SAMC!H3+PHUA!H3+SAMA!H3+GMTU!H3+PHLY!AO3 -> 0 | AP3: =WANG!I3+PUNA!I3+GELA!I3+ZEMG!I3+TRON!I3+BUMA!I3+SARA!I3+TSIR!I3+DGNA!I3+PANG!I3+DPLA!I3+SJKA!I3+LUNT!I3+SAMC!I3+PHUA!I3+SAMA!I3+GMTU!I3+PHLY!AP3 -> 0 | AQ3: =WANG!J3+PUNA!J3+GELA!J3+ZEMG!J3+TRON!J3+BUMA!J3+SARA!J3+TSIR!J3+DGNA!J3+PANG!J3+DPLA!J3+SJKA!J3+LUNT!J3+SAMC!J3+PHUA!J3+SAMA!J3+GMTU!J3+PHLY!AQ3 -> 0 | AR3: =WANG!K3+PUNA!K3+GELA!K3+ZEMG!K3+TRON!K3+BUMA!K3+SARA!K3+TSIR!K3+DGNA!K3+PANG!K3+DPLA!K3+SJKA!K3+LUNT!K3+SAMC!K3+PHUA!K3+SAMA!K3+GMTU!K3+PHLY!AR3 -> 1 | AS3: =WANG!L3+PUNA!L3+GELA!L3+ZEMG!L3+TRON!L3+BUMA!L3+SARA!L3+TSIR!L3+DGNA!L3+PANG!L3+DPLA!L3+SJKA!L3+LUNT!L3+SAMC!L3+PHUA!L3+SAMA!L3+GMTU!L3+PHLY!AS3 -> 0 | AT3: =WANG!M3+PUNA!M3+GELA!M3+ZEMG!M3+TRON!M3+BUMA!M3+SARA!M3+TSIR!M3+DGNA!M3+PANG!M3+DPLA!M3+SJKA!M3+LUNT!M3+SAMC!M3+PHUA!M3+SAMA!M3+GMTU!M3+PHLY!AT3 -> 0 | AU3: =WANG!N3+PUNA!N3+GELA!N3+ZEMG!N3+TRON!N3+BUMA!N3+SARA!N3+TSIR!N3+DGNA!N3+PANG!N3+DPLA!N3+SJKA!N3+LUNT!N3+SAMC!N3+PHUA!N3+SAMA!N3+GMTU!N3+PHLY!AU3 -> 1 | AV3: =WANG!O3+PUNA!O3+GELA!O3+ZEMG!O3+TRON!O3+BUMA!O3+SARA!O3+TSIR!O3+DGNA!O3+PANG!O3+DPLA!O3+SJKA!O3+LUNT!O3+SAMC!O3+PHUA!O3+SAMA!O3+GMTU!O3+PHLY!AV3 -> 0 | ... BW3: =WANG!AP3+PUNA!AP3+GELA!AP3+ZEMG!AP3+TRON!AP3+BUMA!AP3+SARA!AP3+TSIR!AP3+DGNA!AP3+PANG!AP3+DPLA!AP3+SJKA!AP3+LUNT!AP3+SAMC!AP3+PHUA!AP3+SAMA!AP3+GMTU!AP3+PHLY!BW3 -> 10800 | BY3: =HAA!H3+WANG!AR3+PUNA!AR3+GASA!H3+GELA!AR3+ZEMG!AR3+TRON!AR3+BUMA!AR3+SARA!AR3+TSIR!AR3+DGNA!AR3+PANG!AR3+DPLA!AR3+SJKA!AR3+TRAG!H3+LUNT!AR3+WRMG!H3+NGLM!H3+SAMC!AR3+PHUA!AR3+GEDU!H3+SAMA!AR3+TCHG!H3+GMTU!AR3+PHLY!BY3 -> 3 | BZ3: =HAA!I3+WANG!AS3+PUNA!AS3+GASA!I3+GELA!AS3+ZEMG!AS3+TRON!AS3+BUMA!AS3+SARA!AS3+TSIR!AS3+DGNA!AS3+PANG!AS3+DPLA!AS3+SJKA!AS3+TRAG!I3+LUNT!AS3+WRMG!I3+NGLM!I3+SAMC!AS3+PHUA!AS3+GEDU!I3+SAMA!AS3+TCHG!I3+GMTU!AS3+PHLY!BZ3 -> 0 | CA3: =HAA!J3+WANG!AT3+PUNA!AT3+GASA!J3+GELA!AT3+ZEMG!AT3+TRON!AT3+BUMA!AT3+SARA!AT3+TSIR!AT3+DGNA!AT3+PANG!AT3+DPLA!AT3+SJKA!AT3+TRAG!J3+LUNT!AT3+WRMG!J3+NGLM!J3+SAMC!AT3+PHUA!AT3+GEDU!J3+SAMA!AT3+TCHG!J3+GMTU!AT3+PHLY!CA3 -> 2 | CB3: =HAA!K3+WANG!AU3+PUNA!AU3+GASA!K3+GELA!AU3+ZEMG!AU3+TRON!AU3+BUMA!AU3+SARA!AU3+TSIR!AU3+DGNA!AU3+PANG!AU3+DPLA!AU3+SJKA!AU3+TRAG!K3+LUNT!AU3+WRMG!K3+NGLM!K3+SAMC!AU3+PHUA!AU3+GEDU!K3+SAMA!AU3+TCHG!K3+GMTU!AU3+PHLY!CB3 -> 0 | CC3: =HAA!L3+WANG!AV3+PUNA!AV3+GASA!L3+GELA!AV3+ZEMG!AV3+TRON!AV3+BUMA!AV3+SARA!AV3+TSIR!AV3+DGNA!AV3+PANG!AV3+DPLA!AV3+SJKA!AV3+TRAG!L3+LUNT!AV3+WRMG!L3+NGLM!L3+SAMC!AV3+PHUA!AV3+GEDU!L3+SAMA!AV3+TCHG!L3+GMTU!AV3+PHLY!CC3 -> 0 | CD3: =HAA!M3+WANG!AW3+PUNA!AW3+GASA!M3+GELA!AW3+ZEMG!AW3+TRON!AW3+BUMA!AW3+SARA!AW3+TSIR!AW3+DGNA!AW3+PANG!AW3+DPLA!AW3+SJKA!AW3+TRAG!M3+LUNT!AW3+WRMG!M3+NGLM!M3+SAMC!AW3+PHUA!AW3+GEDU!M3+SAMA!AW3+TCHG!M3+GMTU!AW3+PHLY!CD3 -> 0 | CE3: =HAA!N3+WANG!AX3+PUNA!AX3+GASA!N3+GELA!AX3+ZEMG!AX3+TRON!AX3+BUMA!AX3+SARA!AX3+TSIR!AX3+DGNA!AX3+PANG!AX3+DPLA!AX3+SJKA!AX3+TRAG!N3+LUNT!AX3+WRMG!N3+NGLM!N3+SAMC!AX3+PHUA!AX3+GEDU!N3+SAMA!AX3+TCHG!N3+GMTU!AX3+PHLY!CE3 -> 1 | CF3: =HAA!O3+WANG!AY3+PUNA!AY3+GASA!O3+GELA!AY3+ZEMG!AY3+TRON!AY3+BUMA!AY3+SARA!AY3+TSIR!AY3+DGNA!AY3+PANG!AY3+DPLA!AY3+SJKA!AY3+TRAG!O3+LUNT!AY3+WRMG!O3+NGLM!O3+SAMC!AY3+PHUA!AY3+GEDU!O3+SAMA!AY3+TCHG!O3+GMTU!AY3+PHLY!CF3 -> 1 | ... DF3: =HAA!AO3+WANG!BY3+PUNA!BY3+GASA!AO3+GELA!BY3+ZEMG!BY3+TRON!BY3+BUMA!BY3+SARA!BY3+TSIR!BY3+DGNA!BY3+PANG!BY3+DPLA!BY3+SJKA!BY3+TRAG!AO3+LUNT!BY3+WRMG!AO3+NGLM!AO3+SAMC!BY3+PHUA!BY3+GEDU!AO3+SAMA!BY3+TCHG!AO3+GMTU!BY3+PHLY!DF3 -> 11400 | DG3: =AJ3+BT3+DC3 -> 74 | DH3: =C3*DG3 -> 22200 | DI3: =D3*DG3 -> 26640 | DJ3: =E3*DG3 -> 4440 | DK3: 30 | DL3: =DG3*DK3 -> 2220 | DN3: =PARO!H3+HAA!AQ3+WANG!CA3+PUNA!CA3+GASA!AQ3+GELA!CA3+ZEMG!CA3+TRON!CA3+BUMA!CA3+SARA!CA3+TSIR!CA3+DGNA!CA3+PANG!CA3+DPLA!CA3+SJKA!CA3+TRAG!AQ3+MONA!H3+LUNT!CA3+TYSE!H3+PEMA!H3+KNLG!H3+RJNG!H3+WRMG!AQ3+DUSM!H3+GYPG!H3+NGLM!AQ3+SAMC!CA3+PHUA!CA3+TSMA!H3+GEDU!AQ3+SAMA!CA3+TCHG!AQ3+GMTU!CA3+LHAM!H3+PHLY!DH3 -> 0 | DO3: =PARO!I3+HAA!AR3+WANG!CB3+PUNA!CB3+GASA!AR3+GELA!CB3+ZEMG!CB3+TRON!CB3+BUMA!CB3+SARA!CB3+TSIR!CB3+DGNA!CB3+PANG!CB3+DPLA!CB3+SJKA!CB3+TRAG!AR3+MONA!I3+LUNT!CB3+TYSE!I3+PEMA!I3+KNLG!I3+RJNG!I3+WRMG!AR3+DUSM!I3+GYPG!I3+NGLM!AR3+SAMC!CB3+PHUA!CB3+TSMA!I3+GEDU!AR3+SAMA!CB3+TCHG!AR3+GMTU!CB3+LHAM!I3+PHLY!DI3 -> 0 | DP3: =PARO!J3+HAA!AS3+WANG!CC3+PUNA!CC3+GASA!AS3+GELA!CC3+ZEMG!CC3+TRON!CC3+BUMA!CC3+SARA!CC3+TSIR!CC3+DGNA!CC3+PANG!CC3+DPLA!CC3+SJKA!CC3+TRAG!AS3+MONA!J3+LUNT!CC3+TYSE!J3+PEMA!J3+KNLG!J3+RJNG!J3+WRMG!AS3+DUSM!J3+GYPG!J3+NGLM!AS3+SAMC!CC3+PHUA!CC3+TSMA!J3+GEDU!AS3+SAMA!CC3+TCHG!AS3+GMTU!CC3+LHAM!J3+PHLY!DJ3 -> 0 | DQ3: =PARO!K3+HAA!AT3+WANG!CD3+PUNA!CD3+GASA!AT3+GELA!CD3+ZEMG!CD3+TRON!CD3+BUMA!CD3+SARA!CD3+TSIR!CD3+DGNA!CD3+PANG!CD3+DPLA!CD3+SJKA!CD3+TRAG!AT3+MONA!K3+LUNT!CD3+TYSE!K3+PEMA!K3+KNLG!K3+RJNG!K3+WRMG!AT3+DUSM!K3+GYPG!K3+NGLM!AT3+SAMC!CD3+PHUA!CD3+TSMA!K3+GEDU!AT3+SAMA!CD3+TCHG!AT3+GMTU!CD3+LHAM!K3+PHLY!DK3 -> 0 | DR3: =PARO!L3+HAA!AU3+WANG!CE3+PUNA!CE3+GASA!AU3+GELA!CE3+ZEMG!CE3+TRON!CE3+BUMA!CE3+SARA!CE3+TSIR!CE3+DGNA!CE3+PANG!CE3+DPLA!CE3+SJKA!CE3+TRAG!AU3+MONA!L3+LUNT!CE3+TYSE!L3+PEMA!L3+KNLG!L3+RJNG!L3+WRMG!AU3+DUSM!L3+GYPG!L3+NGLM!AU3+SAMC!CE3+PHUA!CE3+TSMA!L3+GEDU!AU3+SAMA!CE3+TCHG!AU3+GMTU!CE3+LHAM!L3+PHLY!DL3 -> 3 | DS3: =PARO!M3+HAA!AV3+WANG!CF3+PUNA!CF3+GASA!AV3+GELA!CF3+ZEMG!CF3+TRON!CF3+BUMA!CF3+SARA!CF3+TSIR!CF3+DGNA!CF3+PANG!CF3+DPLA!CF3+SJKA!CF3+TRAG!AV3+MONA!M3+LUNT!CF3+TYSE!M3+PEMA!M3+KNLG!M3+RJNG!M3+WRMG!AV3+DUSM!M3+GYPG!M3+NGLM!AV3+SAMC!CF3+PHUA!CF3+TSMA!M3+GEDU!AV3+SAMA!CF3+TCHG!AV3+GMTU!CF3+LHAM!M3+PHLY!DM3 -> 12 | DT3: =PARO!N3+HAA!AW3+WANG!CG3+PUNA!CG3+GASA!AW3+GELA!CG3+ZEMG!CG3+TRON!CG3+BUMA!CG3+SARA!CG3+TSIR!CG3+DGNA!CG3+PANG!CG3+DPLA!CG3+SJKA!CG3+TRAG!AW3+MONA!N3+LUNT!CG3+TYSE!N3+PEMA!N3+KNLG!N3+RJNG!N3+WRMG!AW3+DUSM!N3+GYPG!N3+NGLM!AW3+SAMC!CG3+PHUA!CG3+TSMA!N3+GEDU!AW3+SAMA!CG3+TCHG!AW3+GMTU!CG3+LHAM!N3+PHLY!DN3 -> 0 | DU3: =PARO!O3+HAA!AX3+WANG!CH3+PUNA!CH3+GASA!AX3+GELA!CH3+ZEMG!CH3+TRON!CH3+BUMA!CH3+SARA!CH3+TSIR!CH3+DGNA!CH3+PANG!CH3+DPLA!CH3+SJKA!CH3+TRAG!AX3+MONA!O3+LUNT!CH3+TYSE!O3+PEMA!O3+KNLG!O3+RJNG!O3+WRMG!AX3+DUSM!O3+GYPG!O3+NGLM!AX3+SAMC!CH3+PHUA!CH3+TSMA!O3+GEDU!AX3+SAMA!CH3+TCHG!AX3+GMTU!CH3+LHAM!O3+PHLY!DO3 -> 0 | ... EV3: =PARO!AP3+HAA!BY3+WANG!DI3+PUNA!DI3+GASA!BY3+GELA!DI3+ZEMG!DI3+TRON!DI3+BUMA!DI3+SARA!DI3+TSIR!DI3+DGNA!DI3+PANG!DI3+DPLA!DI3+SJKA!DI3+TRAG!BY3+MONA!AP3+LUNT!DI3+TYSE!AP3+PEMA!AP3+KNLG!AP3+RJNG!AP3+WRMG!BY3+DUSM!AP3+GYPG!AP3+NGLM!BY3+SAMC!DI3+PHUA!DI3+TSMA!AP3+GEDU!BY3+SAMA!DI3+TCHG!BY3+GMTU!DI3+LHAM!AP3+PHLY!EP3 -> 9300 | EX3: =PARO!AR3+HAA!CA3+WANG!DK3+PUNA!DK3+GASA!CA3+GELA!DK3+ZEMG!DK3+TRON!DK3+BUMA!DK3+SARA!DK3+TSIR!DK3+DGNA!DK3+PANG!DK3+DPLA!DK3+SJKA!DK3+TRAG!CA3+MONA!AR3+LUNT!DK3+TYSE!AR3+PEMA!AR3+KNLG!AR3+RJNG!AR3+WRMG!CA3+DUSM!AR3+GYPG!AR3+NGLM!CA3+SAMC!DK3+PHUA!DK3+TSMA!AR3+GEDU!CA3+SAMA!DK3+TCHG!CA3+GMTU!DK3+LHAM!AR3+PHLY!ER3 -> 0 | EY3: =PARO!AS3+HAA!CB3+WANG!DL3+PUNA!DL3+GASA!CB3+GELA!DL3+ZEMG!DL3+TRON!DL3+BUMA!DL3+SARA!DL3+TSIR!DL3+DGNA!DL3+PANG!DL3+DPLA!DL3+SJKA!DL3+TRAG!CB3+MONA!AS3+LUNT!DL3+TYSE!AS3+PEMA!AS3+KNLG!AS3+RJNG!AS3+WRMG!CB3+DUSM!AS3+GYPG!AS3+NGLM!CB3+SAMC!DL3+PHUA!DL3+TSMA!AS3+GEDU!CB3+SAMA!DL3+TCHG!CB3+GMTU!DL3+LHAM!AS3+PHLY!ES3 -> 0 | EZ3: =PARO!AT3+HAA!CC3+WANG!DM3+PUNA!DM3+GASA!CC3+GELA!DM3+ZEMG!DM3+TRON!DM3+BUMA!DM3+SARA!DM3+TSIR!DM3+DGNA!DM3+PANG!DM3+DPLA!DM3+SJKA!DM3+TRAG!CC3+MONA!AT3+LUNT!DM3+TYSE!AT3+PEMA!AT3+KNLG!AT3+RJNG!AT3+WRMG!CC3+DUSM!AT3+GYPG!AT3+NGLM!CC3+SAMC!DM3+PHUA!DM3+TSMA!AT3+GEDU!CC3+SAMA!DM3+TCHG!CC3+GMTU!DM3+LHAM!AT3+PHLY!ET3 -> 2 | FA3: =PARO!AU3+HAA!CD3+WANG!DN3+PUNA!DN3+GASA!CD3+GELA!DN3+ZEMG!DN3+TRON!DN3+BUMA!DN3+SARA!DN3+TSIR!DN3+DGNA!DN3+PANG!DN3+DPLA!DN3+SJKA!DN3+TRAG!CD3+MONA!AU3+LUNT!DN3+TYSE!AU3+PEMA!AU3+KNLG!AU3+RJNG!AU3+WRMG!CD3+DUSM!AU3+GYPG!AU3+NGLM!CD3+SAMC!DN3+PHUA!DN3+TSMA!AU3+GEDU!CD3+SAMA!DN3+TCHG!CD3+GMTU!DN3+LHAM!AU3+PHLY!EU3 -> 2 | FB3: =PARO!AV3+HAA!CE3+WANG!DO3+PUNA!DO3+GASA!CE3+GELA!DO3+ZEMG!DO3+TRON!DO3+BUMA!DO3+SARA!DO3+TSIR!DO3+DGNA!DO3+PANG!DO3+DPLA!DO3+SJKA!DO3+TRAG!CE3+MONA!AV3+LUNT!DO3+TYSE!AV3+PEMA!AV3+KNLG!AV3+RJNG!AV3+WRMG!CE3+DUSM!AV3+GYPG!AV3+NGLM!CE3+SAMC!DO3+PHUA!DO3+TSMA!AV3+GEDU!CE3+SAMA!DO3+TCHG!CE3+GMTU!DO3+LHAM!AV3+PHLY!EV3 -> 2 | FC3: =PARO!AW3+HAA!CF3+WANG!DP3+PUNA!DP3+GASA!CF3+GELA!DP3+ZEMG!DP3+TRON!DP3+BUMA!DP3+SARA!DP3+TSIR!DP3+DGNA!DP3+PANG!DP3+DPLA!DP3+SJKA!DP3+TRAG!CF3+MONA!AW3+LUNT!DP3+TYSE!AW3+PEMA!AW3+KNLG!AW3+RJNG!AW3+WRMG!CF3+DUSM!AW3+GYPG!AW3+NGLM!CF3+SAMC!DP3+PHUA!DP3+TSMA!AW3+GEDU!CF3+SAMA!DP3+TCHG!CF3+GMTU!DP3+LHAM!AW3+PHLY!EW3 -> 0 | FD3: =PARO!AX3+HAA!CG3+WANG!DQ3+PUNA!DQ3+GASA!CG3+GELA!DQ3+ZEMG!DQ3+TRON!DQ3+BUMA!DQ3+SARA!DQ3+TSIR!DQ3+DGNA!DQ3+PANG!DQ3+DPLA!DQ3+SJKA!DQ3+TRAG!CG3+MONA!AX3+LUNT!DQ3+TYSE!AX3+PEMA!AX3+KNLG!AX3+RJNG!AX3+WRMG!CG3+DUSM!AX3+GYPG!AX3+NGLM!CG3+SAMC!DQ3+PHUA!DQ3+TSMA!AX3+GEDU!CG3+SAMA!DQ3+TCHG!CG3+GMTU!DQ3+LHAM!AX3+PHLY!EX3 -> 7 | FE3: =PARO!AY3+HAA!CH3+WANG!DR3+PUNA!DR3+GASA!CH3+GELA!DR3+ZEMG!DR3+TRON!DR3+BUMA!DR3+SARA!DR3+TSIR!DR3+DGNA!DR3+PANG!DR3+DPLA!DR3+SJKA!DR3+TRAG!CH3+MONA!AY3+LUNT!DR3+TYSE!AY3+PEMA!AY3+KNLG!AY3+RJNG!AY3+WRMG!CH3+DUSM!AY3+GYPG!AY3+NGLM!CH3+SAMC!DR3+PHUA!DR3+TSMA!AY3+GEDU!CH3+SAMA!DR3+TCHG!CH3+GMTU!DR3+LHAM!AY3+PHLY!EY3 -> 0 | ... GA3: =PARO!BU3+HAA!DD3+WANG!EN3+PUNA!EN3+GASA!DD3+GELA!EN3+ZEMG!EN3+TRON!EN3+BUMA!EN3+SARA!EN3+TSIR!EN3+DGNA!EN3+PANG!EN3+DPLA!EN3+SJKA!EN3+TRAG!DD3+MONA!BU3+LUNT!EN3+TYSE!BU3+PEMA!BU3+KNLG!BU3+RJNG!BU3+WRMG!DD3+DUSM!BU3+GYPG!BU3+NGLM!DD3+SAMC!EN3+PHUA!EN3+TSMA!BU3+GEDU!DD3+SAMA!EN3+TCHG!DD3+GMTU!EN3+LHAM!BU3+PHLY!FU3 -> 0 | GB3: =PARO!BV3+HAA!DE3+WANG!EO3+PUNA!EO3+GASA!DE3+GELA!EO3+ZEMG!EO3+TRON!EO3+BUMA!EO3+SARA!EO3+TSIR!EO3+DGNA!EO3+PANG!EO3+DPLA!EO3+SJKA!EO3+TRAG!DE3+MONA!BW3+LUNT!EO3+TYSE!BW3+PEMA!BW3+KNLG!BW3+RJNG!BV3+WRMG!DE3+DUSM!BW3+GYPG!BW3+NGLM!DE3+SAMC!EO3+PHUA!EO3+TSMA!BV3+GEDU!DE3+SAMA!EO3+TCHG!DE3+GMTU!EO3+LHAM!BV3+PHLY!FV3 -> 26 | GC3: =PARO!BW3+HAA!DF3+WANG!EP3+PUNA!EP3+GASA!DF3+GELA!EP3+ZEMG!EP3+TRON!EP3+BUMA!EP3+SARA!EP3+TSIR!EP3+DGNA!EP3+PANG!EP3+DPLA!EP3+SJKA!EP3+TRAG!DF3+MONA!BX3+LUNT!EP3+TYSE!BX3+PEMA!BX3+KNLG!BX3+RJNG!BW3+WRMG!DF3+DUSM!BX3+GYPG!BX3+NGLM!DF3+SAMC!EP3+PHUA!EP3+TSMA!BW3+GEDU!DF3+SAMA!EP3+TCHG!DF3+GMTU!EP3+LHAM!BW3+PHLY!FW3 -> 9360 | GD3: =PARO!BX3+HAA!DG3+WANG!EQ3+PUNA!EQ3+GASA!DG3+GELA!EQ3+ZEMG!EQ3+TRON!EQ3+BUMA!EQ3+SARA!EQ3+TSIR!EQ3+DGNA!EQ3+PANG!EQ3+DPLA!EQ3+SJKA!EQ3+TRAG!DG3+MONA!BY3+LUNT!EQ3+TYSE!BY3+PEMA!BY3+KNLG!BY3+RJNG!BX3+WRMG!DG3+DUSM!BY3+GYPG!BY3+NGLM!DG3+SAMC!EQ3+PHUA!EQ3+TSMA!BX3+GEDU!DG3+SAMA!EQ3+TCHG!DG3+GMTU!EQ3+LHAM!BX3+PHLY!FX3 -> 1560 | GE3: =PARO!BY3+HAA!DH3+WANG!ER3+PUNA!ER3+GASA!DH3+GELA!ER3+ZEMG!ER3+TRON!ER3+BUMA!ER3+SARA!ER3+TSIR!ER3+DGNA!ER3+PANG!ER3+DPLA!ER3+SJKA!ER3+TRAG!DH3+MONA!BZ3+LUNT!ER3+TYSE!BZ3+PEMA!BZ3+KNLG!BZ3+RJNG!BY3+WRMG!DH3+DUSM!BZ3+GYPG!BZ3+NGLM!DH3+SAMC!ER3+PHUA!ER3+TSMA!BY3+GEDU!DH3+SAMA!ER3+TCHG!DH3+GMTU!ER3+LHAM!BY3+PHLY!FY3 -> 7800 | GG3: =PARO!CA3+HAA!DJ3+WANG!ET3+PUNA!ET3+GASA!DJ3+GELA!ET3+ZEMG!ET3+TRON!ET3+BUMA!ET3+SARA!ET3+TSIR!ET3+DGNA!ET3+PANG!ET3+DPLA!ET3+SJKA!ET3+TRAG!DJ3+MONA!CB3+LUNT!ET3+TYSE!CB3+PEMA!CB3+KNLG!CB3+RJNG!CA3+WRMG!DJ3+DUSM!CB3+GYPG!CB3+NGLM!DJ3+SAMC!ET3+PHUA!ET3+TSMA!CA3+GEDU!DJ3+SAMA!ET3+TCHG!DJ3+GMTU!ET3+LHAM!CA3+PHLY!GA3 -> 0 | GH3: =PARO!CB3+HAA!DK3+WANG!EU3+PUNA!EU3+GASA!DK3+GELA!EU3+ZEMG!EU3+TRON!EU3+BUMA!EU3+SARA!EU3+TSIR!EU3+DGNA!EU3+PANG!EU3+DPLA!EU3+SJKA!EU3+TRAG!DK3+MONA!CC3+LUNT!EU3+TYSE!CC3+PEMA!CC3+KNLG!CC3+RJNG!CB3+WRMG!DK3+DUSM!CC3+GYPG!CC3+NGLM!DK3+SAMC!EU3+PHUA!EU3+TSMA!CB3+GEDU!DK3+SAMA!EU3+TCHG!DK3+GMTU!EU3+LHAM!CB3+PHLY!GB3 -> 0 | GI3: =PARO!CC3+HAA!DL3+WANG!EV3+PUNA!EV3+GASA!DL3+GELA!EV3+ZEMG!EV3+TRON!EV3+BUMA!EV3+SARA!EV3+TSIR!EV3+DGNA!EV3+PANG!EV3+DPLA!EV3+SJKA!EV3+TRAG!DL3+MONA!CD3+LUNT!EV3+TYSE!CD3+PEMA!CD3+KNLG!CD3+RJNG!CC3+WRMG!DL3+DUSM!CD3+GYPG!CD3+NGLM!DL3+SAMC!EV3+PHUA!EV3+TSMA!CC3+GEDU!DL3+SAMA!EV3+TCHG!DL3+GMTU!EV3+LHAM!CC3+PHLY!GC3 -> 2 | GJ3: =PARO!CD3+HAA!DM3+WANG!EW3+PUNA!EW3+GASA!DM3+GELA!EW3+ZEMG!EW3+TRON!EW3+BUMA!EW3+SARA!EW3+TSIR!EW3+DGNA!EW3+PANG!EW3+DPLA!EW3+SJKA!EW3+TRAG!DM3+MONA!CE3+LUNT!EW3+TYSE!CE3+PEMA!CE3+KNLG!CE3+RJNG!CD3+WRMG!DM3+DUSM!CE3+GYPG!CE3+NGLM!DM3+SAMC!EW3+PHUA!EW3+TSMA!CD3+GEDU!DM3+SAMA!EW3+TCHG!DM3+GMTU!EW3+LHAM!CD3+PHLY!GD3 -> 2 | GK3: =PARO!CE3+HAA!DN3+WANG!EX3+PUNA!EX3+GASA!DN3+GELA!EX3+ZEMG!EX3+TRON!EX3+BUMA!EX3+SARA!EX3+TSIR!EX3+DGNA!EX3+PANG!EX3+DPLA!EX3+SJKA!EX3+TRAG!DN3+MONA!CF3+LUNT!EX3+TYSE!CF3+PEMA!CF3+KNLG!CF3+RJNG!CE3+WRMG!DN3+DUSM!CF3+GYPG!CF3+NGLM!DN3+SAMC!EX3+PHUA!EX3+TSMA!CE3+GEDU!DN3+SAMA!EX3+TCHG!DN3+GMTU!EX3+LHAM!CE3+PHLY!GE3 -> 0 | GL3: =PARO!CF3+HAA!DO3+WANG!EY3+PUNA!EY3+GASA!DO3+GELA!EY3+ZEMG!EY3+TRON!EY3+BUMA!EY3+SARA!EY3+TSIR!EY3+DGNA!EY3+PANG!EY3+DPLA!EY3+SJKA!EY3+TRAG!DO3+MONA!CG3+LUNT!EY3+TYSE!CG3+PEMA!CG3+KNLG!CG3+RJNG!CF3+WRMG!DO3+DUSM!CG3+GYPG!CG3+NGLM!DO3+SAMC!EY3+PHUA!EY3+TSMA!CF3+GEDU!DO3+SAMA!EY3+TCHG!DO3+GMTU!EY3+LHAM!CF3+PHLY!GF3 -> 0 | GM3: =PARO!CG3+HAA!DP3+WANG!EZ3+PUNA!EZ3+GASA!DP3+GELA!EZ3+ZEMG!EZ3+TRON!EZ3+BUMA!EZ3+SARA!EZ3+TSIR!EZ3+DGNA!EZ3+PANG!EZ3+DPLA!EZ3+SJKA!EZ3+TRAG!DP3+MONA!CH3+LUNT!EZ3+TYSE!CH3+PEMA!CH3+KNLG!CH3+RJNG!CG3+WRMG!DP3+DUSM!CH3+GYPG!CH3+NGLM!DP3+SAMC!EZ3+PHUA!EZ3+TSMA!CG3+GEDU!DP3+SAMA!EZ3+TCHG!DP3+GMTU!EZ3+LHAM!CG3+PHLY!GG3 -> 0 | GN3: =PARO!CH3+HAA!DQ3+WANG!FA3+PUNA!FA3+GASA!DQ3+GELA!FA3+ZEMG!FA3+TRON!FA3+BUMA!FA3+SARA!FA3+TSIR!FA3+DGNA!FA3+PANG!FA3+DPLA!FA3+SJKA!FA3+TRAG!DQ3+MONA!CI3+LUNT!FA3+TYSE!CI3+PEMA!CI3+KNLG!CI3+RJNG!CH3+WRMG!DQ3+DUSM!CI3+GYPG!CI3+NGLM!DQ3+SAMC!FA3+PHUA!FA3+TSMA!CH3+GEDU!DQ3+SAMA!FA3+TCHG!DQ3+GMTU!FA3+LHAM!CH3+PHLY!GH3 -> 0 | ... HO3: =PARO!DI3+HAA!ER3+WANG!GB3+PUNA!GB3+GASA!ER3+GELA!GB3+ZEMG!GB3+TRON!GB3+BUMA!GB3+SARA!GB3+TSIR!GB3+DGNA!GB3+PANG!GB3+DPLA!GB3+SJKA!GB3+TRAG!ER3+MONA!DJ3+LUNT!GB3+TYSE!DJ3+PEMA!DJ3+KNLG!DJ3+RJNG!DI3+WRMG!ER3+DUSM!DJ3+GYPG!DJ3+NGLM!ER3+SAMC!GB3+PHUA!GB3+TSMA!DI3+GEDU!ER3+SAMA!GB3+TCHG!ER3+GMTU!GB3+LHAM!DI3+PHLY!HI3 -> 3900 | HQ3: =ES3+GB3+HL3 -> 70 | HR3: =C3*HQ3 -> 21000 | HS3: =D3*HQ3 -> 25200 | HT3: =E3*HQ3 -> 4200 | HU3: 30 | HV3: =HQ3*HU3 -> 2100 | IN3: =AJ3+BT3+DC3+ES3+GB3+HL3 -> 144 | IO3: =AK3+BU3+DD3+ET3+GC3+HM3 -> 51840 | IP3: =AL3+BV3+DE3+EU3+GD3+HN3 -> 8640 | IQ3: =AM3+BW3+DF3+EV3+GE3+HO3 -> 43200 | IR3: =SUM(IN3:IN6) -> 566
A4: 2 | B4: Himalayan Gooseberry tea | C4: 300 | D4: 360 | E4: =D4-C4 -> 60 | I4: =PHLY!I4 -> 0 | J4: =PHLY!J4 -> 0 | K4: =PHLY!K4 -> 0 | L4: =PHLY!L4 -> 0 | M4: =PHLY!M4 -> 0 | N4: =PHLY!N4 -> 0 | O4: =PHLY!O4 -> 0 | P4: =PHLY!P4 -> 0 | ... AM4: =PHLY!AM4 -> 600 | AO4: =WANG!H4+PUNA!H4+GELA!H4+ZEMG!H4+TRON!H4+BUMA!H4+SARA!H4+TSIR!H4+DGNA!H4+PANG!H4+DPLA!H4+SJKA!H4+LUNT!H4+SAMC!H4+PHUA!H4+SAMA!H4+GMTU!H4+PHLY!AO4 -> 0 | AP4: =WANG!I4+PUNA!I4+GELA!I4+ZEMG!I4+TRON!I4+BUMA!I4+SARA!I4+TSIR!I4+DGNA!I4+PANG!I4+DPLA!I4+SJKA!I4+LUNT!I4+SAMC!I4+PHUA!I4+SAMA!I4+GMTU!I4+PHLY!AP4 -> 0 | AQ4: =WANG!J4+PUNA!J4+GELA!J4+ZEMG!J4+TRON!J4+BUMA!J4+SARA!J4+TSIR!J4+DGNA!J4+PANG!J4+DPLA!J4+SJKA!J4+LUNT!J4+SAMC!J4+PHUA!J4+SAMA!J4+GMTU!J4+PHLY!AQ4 -> 0 | AR4: =WANG!K4+PUNA!K4+GELA!K4+ZEMG!K4+TRON!K4+BUMA!K4+SARA!K4+TSIR!K4+DGNA!K4+PANG!K4+DPLA!K4+SJKA!K4+LUNT!K4+SAMC!K4+PHUA!K4+SAMA!K4+GMTU!K4+PHLY!AR4 -> 0 | AS4: =WANG!L4+PUNA!L4+GELA!L4+ZEMG!L4+TRON!L4+BUMA!L4+SARA!L4+TSIR!L4+DGNA!L4+PANG!L4+DPLA!L4+SJKA!L4+LUNT!L4+SAMC!L4+PHUA!L4+SAMA!L4+GMTU!L4+PHLY!AS4 -> 1 | AT4: =WANG!M4+PUNA!M4+GELA!M4+ZEMG!M4+TRON!M4+BUMA!M4+SARA!M4+TSIR!M4+DGNA!M4+PANG!M4+DPLA!M4+SJKA!M4+LUNT!M4+SAMC!M4+PHUA!M4+SAMA!M4+GMTU!M4+PHLY!AT4 -> 0 | AU4: =WANG!N4+PUNA!N4+GELA!N4+ZEMG!N4+TRON!N4+BUMA!N4+SARA!N4+TSIR!N4+DGNA!N4+PANG!N4+DPLA!N4+SJKA!N4+LUNT!N4+SAMC!N4+PHUA!N4+SAMA!N4+GMTU!N4+PHLY!AU4 -> 3 | AV4: =WANG!O4+PUNA!O4+GELA!O4+ZEMG!O4+TRON!O4+BUMA!O4+SARA!O4+TSIR!O4+DGNA!O4+PANG!O4+DPLA!O4+SJKA!O4+LUNT!O4+SAMC!O4+PHUA!O4+SAMA!O4+GMTU!O4+PHLY!AV4 -> 0 | ... BW4: =WANG!AP4+PUNA!AP4+GELA!AP4+ZEMG!AP4+TRON!AP4+BUMA!AP4+SARA!AP4+TSIR!AP4+DGNA!AP4+PANG!AP4+DPLA!AP4+SJKA!AP4+LUNT!AP4+SAMC!AP4+PHUA!AP4+SAMA!AP4+GMTU!AP4+PHLY!BW4 -> 13800 | BY4: =HAA!H4+WANG!AR4+PUNA!AR4+GASA!H4+GELA!AR4+ZEMG!AR4+TRON!AR4+BUMA!AR4+SARA!AR4+TSIR!AR4+DGNA!AR4+PANG!AR4+DPLA!AR4+SJKA!AR4+TRAG!H4+LUNT!AR4+WRMG!H4+NGLM!H4+SAMC!AR4+PHUA!AR4+GEDU!H4+SAMA!AR4+TCHG!H4+GMTU!AR4+PHLY!BY4 -> 0 | BZ4: =HAA!I4+WANG!AS4+PUNA!AS4+GASA!I4+GELA!AS4+ZEMG!AS4+TRON!AS4+BUMA!AS4+SARA!AS4+TSIR!AS4+DGNA!AS4+PANG!AS4+DPLA!AS4+SJKA!AS4+TRAG!I4+LUNT!AS4+WRMG!I4+NGLM!I4+SAMC!AS4+PHUA!AS4+GEDU!I4+SAMA!AS4+TCHG!I4+GMTU!AS4+PHLY!BZ4 -> 0 | CA4: =HAA!J4+WANG!AT4+PUNA!AT4+GASA!J4+GELA!AT4+ZEMG!AT4+TRON!AT4+BUMA!AT4+SARA!AT4+TSIR!AT4+DGNA!AT4+PANG!AT4+DPLA!AT4+SJKA!AT4+TRAG!J4+LUNT!AT4+WRMG!J4+NGLM!J4+SAMC!AT4+PHUA!AT4+GEDU!J4+SAMA!AT4+TCHG!J4+GMTU!AT4+PHLY!CA4 -> 0 | CB4: =HAA!K4+WANG!AU4+PUNA!AU4+GASA!K4+GELA!AU4+ZEMG!AU4+TRON!AU4+BUMA!AU4+SARA!AU4+TSIR!AU4+DGNA!AU4+PANG!AU4+DPLA!AU4+SJKA!AU4+TRAG!K4+LUNT!AU4+WRMG!K4+NGLM!K4+SAMC!AU4+PHUA!AU4+GEDU!K4+SAMA!AU4+TCHG!K4+GMTU!AU4+PHLY!CB4 -> 1 | CC4: =HAA!L4+WANG!AV4+PUNA!AV4+GASA!L4+GELA!AV4+ZEMG!AV4+TRON!AV4+BUMA!AV4+SARA!AV4+TSIR!AV4+DGNA!AV4+PANG!AV4+DPLA!AV4+SJKA!AV4+TRAG!L4+LUNT!AV4+WRMG!L4+NGLM!L4+SAMC!AV4+PHUA!AV4+GEDU!L4+SAMA!AV4+TCHG!L4+GMTU!AV4+PHLY!CC4 -> 0 | CD4: =HAA!M4+WANG!AW4+PUNA!AW4+GASA!M4+GELA!AW4+ZEMG!AW4+TRON!AW4+BUMA!AW4+SARA!AW4+TSIR!AW4+DGNA!AW4+PANG!AW4+DPLA!AW4+SJKA!AW4+TRAG!M4+LUNT!AW4+WRMG!M4+NGLM!M4+SAMC!AW4+PHUA!AW4+GEDU!M4+SAMA!AW4+TCHG!M4+GMTU!AW4+PHLY!CD4 -> 0 | CE4: =HAA!N4+WANG!AX4+PUNA!AX4+GASA!N4+GELA!AX4+ZEMG!AX4+TRON!AX4+BUMA!AX4+SARA!AX4+TSIR!AX4+DGNA!AX4+PANG!AX4+DPLA!AX4+SJKA!AX4+TRAG!N4+LUNT!AX4+WRMG!N4+NGLM!N4+SAMC!AX4+PHUA!AX4+GEDU!N4+SAMA!AX4+TCHG!N4+GMTU!AX4+PHLY!CE4 -> 0 | CF4: =HAA!O4+WANG!AY4+PUNA!AY4+GASA!O4+GELA!AY4+ZEMG!AY4+TRON!AY4+BUMA!AY4+SARA!AY4+TSIR!AY4+DGNA!AY4+PANG!AY4+DPLA!AY4+SJKA!AY4+TRAG!O4+LUNT!AY4+WRMG!O4+NGLM!O4+SAMC!AY4+PHUA!AY4+GEDU!O4+SAMA!AY4+TCHG!O4+GMTU!AY4+PHLY!CF4 -> 1 | ... DF4: =HAA!AO4+WANG!BY4+PUNA!BY4+GASA!AO4+GELA!BY4+ZEMG!BY4+TRON!BY4+BUMA!BY4+SARA!BY4+TSIR!BY4+DGNA!BY4+PANG!BY4+DPLA!BY4+SJKA!BY4+TRAG!AO4+LUNT!BY4+WRMG!AO4+NGLM!AO4+SAMC!BY4+PHUA!BY4+GEDU!AO4+SAMA!BY4+TCHG!AO4+GMTU!BY4+PHLY!DF4 -> 12900 | DG4: =AJ4+BT4+DC4 -> 91 | DH4: =C4*DG4 -> 27300 | DI4: =D4*DG4 -> 32760 | DJ4: =E4*DG4 -> 5460 | DK4: 30 | DL4: =DG4*DK4 -> 2730 | DN4: =PARO!H4+HAA!AQ4+WANG!CA4+PUNA!CA4+GASA!AQ4+GELA!CA4+ZEMG!CA4+TRON!CA4+BUMA!CA4+SARA!CA4+TSIR!CA4+DGNA!CA4+PANG!CA4+DPLA!CA4+SJKA!CA4+TRAG!AQ4+MONA!H4+LUNT!CA4+TYSE!H4+PEMA!H4+KNLG!H4+RJNG!H4+WRMG!AQ4+DUSM!H4+GYPG!H4+NGLM!AQ4+SAMC!CA4+PHUA!CA4+TSMA!H4+GEDU!AQ4+SAMA!CA4+TCHG!AQ4+GMTU!CA4+LHAM!H4+PHLY!DH4 -> 0 | DO4: =PARO!I4+HAA!AR4+WANG!CB4+PUNA!CB4+GASA!AR4+GELA!CB4+ZEMG!CB4+TRON!CB4+BUMA!CB4+SARA!CB4+TSIR!CB4+DGNA!CB4+PANG!CB4+DPLA!CB4+SJKA!CB4+TRAG!AR4+MONA!I4+LUNT!CB4+TYSE!I4+PEMA!I4+KNLG!I4+RJNG!I4+WRMG!AR4+DUSM!I4+GYPG!I4+NGLM!AR4+SAMC!CB4+PHUA!CB4+TSMA!I4+GEDU!AR4+SAMA!CB4+TCHG!AR4+GMTU!CB4+LHAM!I4+PHLY!DI4 -> 0 | DP4: =PARO!J4+HAA!AS4+WANG!CC4+PUNA!CC4+GASA!AS4+GELA!CC4+ZEMG!CC4+TRON!CC4+BUMA!CC4+SARA!CC4+TSIR!CC4+DGNA!CC4+PANG!CC4+DPLA!CC4+SJKA!CC4+TRAG!AS4+MONA!J4+LUNT!CC4+TYSE!J4+PEMA!J4+KNLG!J4+RJNG!J4+WRMG!AS4+DUSM!J4+GYPG!J4+NGLM!AS4+SAMC!CC4+PHUA!CC4+TSMA!J4+GEDU!AS4+SAMA!CC4+TCHG!AS4+GMTU!CC4+LHAM!J4+PHLY!DJ4 -> 0 | DQ4: =PARO!K4+HAA!AT4+WANG!CD4+PUNA!CD4+GASA!AT4+GELA!CD4+ZEMG!CD4+TRON!CD4+BUMA!CD4+SARA!CD4+TSIR!CD4+DGNA!CD4+PANG!CD4+DPLA!CD4+SJKA!CD4+TRAG!AT4+MONA!K4+LUNT!CD4+TYSE!K4+PEMA!K4+KNLG!K4+RJNG!K4+WRMG!AT4+DUSM!K4+GYPG!K4+NGLM!AT4+SAMC!CD4+PHUA!CD4+TSMA!K4+GEDU!AT4+SAMA!CD4+TCHG!AT4+GMTU!CD4+LHAM!K4+PHLY!DK4 -> 0 | DR4: =PARO!L4+HAA!AU4+WANG!CE4+PUNA!CE4+GASA!AU4+GELA!CE4+ZEMG!CE4+TRON!CE4+BUMA!CE4+SARA!CE4+TSIR!CE4+DGNA!CE4+PANG!CE4+DPLA!CE4+SJKA!CE4+TRAG!AU4+MONA!L4+LUNT!CE4+TYSE!L4+PEMA!L4+KNLG!L4+RJNG!L4+WRMG!AU4+DUSM!L4+GYPG!L4+NGLM!AU4+SAMC!CE4+PHUA!CE4+TSMA!L4+GEDU!AU4+SAMA!CE4+TCHG!AU4+GMTU!CE4+LHAM!L4+PHLY!DL4 -> 1 | DS4: =PARO!M4+HAA!AV4+WANG!CF4+PUNA!CF4+GASA!AV4+GELA!CF4+ZEMG!CF4+TRON!CF4+BUMA!CF4+SARA!CF4+TSIR!CF4+DGNA!CF4+PANG!CF4+DPLA!CF4+SJKA!CF4+TRAG!AV4+MONA!M4+LUNT!CF4+TYSE!M4+PEMA!M4+KNLG!M4+RJNG!M4+WRMG!AV4+DUSM!M4+GYPG!M4+NGLM!AV4+SAMC!CF4+PHUA!CF4+TSMA!M4+GEDU!AV4+SAMA!CF4+TCHG!AV4+GMTU!CF4+LHAM!M4+PHLY!DM4 -> 10 | DT4: =PARO!N4+HAA!AW4+WANG!CG4+PUNA!CG4+GASA!AW4+GELA!CG4+ZEMG!CG4+TRON!CG4+BUMA!CG4+SARA!CG4+TSIR!CG4+DGNA!CG4+PANG!CG4+DPLA!CG4+SJKA!CG4+TRAG!AW4+MONA!N4+LUNT!CG4+TYSE!N4+PEMA!N4+KNLG!N4+RJNG!N4+WRMG!AW4+DUSM!N4+GYPG!N4+NGLM!AW4+SAMC!CG4+PHUA!CG4+TSMA!N4+GEDU!AW4+SAMA!CG4+TCHG!AW4+GMTU!CG4+LHAM!N4+PHLY!DN4 -> 2 | DU4: =PARO!O4+HAA!AX4+WANG!CH4+PUNA!CH4+GASA!AX4+GELA!CH4+ZEMG!CH4+TRON!CH4+BUMA!CH4+SARA!CH4+TSIR!CH4+DGNA!CH4+PANG!CH4+DPLA!CH4+SJKA!CH4+TRAG!AX4+MONA!O4+LUNT!CH4+TYSE!O4+PEMA!O4+KNLG!O4+RJNG!O4+WRMG!AX4+DUSM!O4+GYPG!O4+NGLM!AX4+SAMC!CH4+PHUA!CH4+TSMA!O4+GEDU!AX4+SAMA!CH4+TCHG!AX4+GMTU!CH4+LHAM!O4+PHLY!DO4 -> 2 | ... EV4: =PARO!AP4+HAA!BY4+WANG!DI4+PUNA!DI4+GASA!BY4+GELA!DI4+ZEMG!DI4+TRON!DI4+BUMA!DI4+SARA!DI4+TSIR!DI4+DGNA!DI4+PANG!DI4+DPLA!DI4+SJKA!DI4+TRAG!BY4+MONA!AP4+LUNT!DI4+TYSE!AP4+PEMA!AP4+KNLG!AP4+RJNG!AP4+WRMG!BY4+DUSM!AP4+GYPG!AP4+NGLM!BY4+SAMC!DI4+PHUA!DI4+TSMA!AP4+GEDU!BY4+SAMA!DI4+TCHG!BY4+GMTU!DI4+LHAM!AP4+PHLY!EP4 -> 8400 | EX4: =PARO!AR4+HAA!CA4+WANG!DK4+PUNA!DK4+GASA!CA4+GELA!DK4+ZEMG!DK4+TRON!DK4+BUMA!DK4+SARA!DK4+TSIR!DK4+DGNA!DK4+PANG!DK4+DPLA!DK4+SJKA!DK4+TRAG!CA4+MONA!AR4+LUNT!DK4+TYSE!AR4+PEMA!AR4+KNLG!AR4+RJNG!AR4+WRMG!CA4+DUSM!AR4+GYPG!AR4+NGLM!CA4+SAMC!DK4+PHUA!DK4+TSMA!AR4+GEDU!CA4+SAMA!DK4+TCHG!CA4+GMTU!DK4+LHAM!AR4+PHLY!ER4 -> 0 | EY4: =PARO!AS4+HAA!CB4+WANG!DL4+PUNA!DL4+GASA!CB4+GELA!DL4+ZEMG!DL4+TRON!DL4+BUMA!DL4+SARA!DL4+TSIR!DL4+DGNA!DL4+PANG!DL4+DPLA!DL4+SJKA!DL4+TRAG!CB4+MONA!AS4+LUNT!DL4+TYSE!AS4+PEMA!AS4+KNLG!AS4+RJNG!AS4+WRMG!CB4+DUSM!AS4+GYPG!AS4+NGLM!CB4+SAMC!DL4+PHUA!DL4+TSMA!AS4+GEDU!CB4+SAMA!DL4+TCHG!CB4+GMTU!DL4+LHAM!AS4+PHLY!ES4 -> 0 | EZ4: =PARO!AT4+HAA!CC4+WANG!DM4+PUNA!DM4+GASA!CC4+GELA!DM4+ZEMG!DM4+TRON!DM4+BUMA!DM4+SARA!DM4+TSIR!DM4+DGNA!DM4+PANG!DM4+DPLA!DM4+SJKA!DM4+TRAG!CC4+MONA!AT4+LUNT!DM4+TYSE!AT4+PEMA!AT4+KNLG!AT4+RJNG!AT4+WRMG!CC4+DUSM!AT4+GYPG!AT4+NGLM!CC4+SAMC!DM4+PHUA!DM4+TSMA!AT4+GEDU!CC4+SAMA!DM4+TCHG!CC4+GMTU!DM4+LHAM!AT4+PHLY!ET4 -> 1 | FA4: =PARO!AU4+HAA!CD4+WANG!DN4+PUNA!DN4+GASA!CD4+GELA!DN4+ZEMG!DN4+TRON!DN4+BUMA!DN4+SARA!DN4+TSIR!DN4+DGNA!DN4+PANG!DN4+DPLA!DN4+SJKA!DN4+TRAG!CD4+MONA!AU4+LUNT!DN4+TYSE!AU4+PEMA!AU4+KNLG!AU4+RJNG!AU4+WRMG!CD4+DUSM!AU4+GYPG!AU4+NGLM!CD4+SAMC!DN4+PHUA!DN4+TSMA!AU4+GEDU!CD4+SAMA!DN4+TCHG!CD4+GMTU!DN4+LHAM!AU4+PHLY!EU4 -> 2 | FB4: =PARO!AV4+HAA!CE4+WANG!DO4+PUNA!DO4+GASA!CE4+GELA!DO4+ZEMG!DO4+TRON!DO4+BUMA!DO4+SARA!DO4+TSIR!DO4+DGNA!DO4+PANG!DO4+DPLA!DO4+SJKA!DO4+TRAG!CE4+MONA!AV4+LUNT!DO4+TYSE!AV4+PEMA!AV4+KNLG!AV4+RJNG!AV4+WRMG!CE4+DUSM!AV4+GYPG!AV4+NGLM!CE4+SAMC!DO4+PHUA!DO4+TSMA!AV4+GEDU!CE4+SAMA!DO4+TCHG!CE4+GMTU!DO4+LHAM!AV4+PHLY!EV4 -> 0 | FC4: =PARO!AW4+HAA!CF4+WANG!DP4+PUNA!DP4+GASA!CF4+GELA!DP4+ZEMG!DP4+TRON!DP4+BUMA!DP4+SARA!DP4+TSIR!DP4+DGNA!DP4+PANG!DP4+DPLA!DP4+SJKA!DP4+TRAG!CF4+MONA!AW4+LUNT!DP4+TYSE!AW4+PEMA!AW4+KNLG!AW4+RJNG!AW4+WRMG!CF4+DUSM!AW4+GYPG!AW4+NGLM!CF4+SAMC!DP4+PHUA!DP4+TSMA!AW4+GEDU!CF4+SAMA!DP4+TCHG!CF4+GMTU!DP4+LHAM!AW4+PHLY!EW4 -> 0 | FD4: =PARO!AX4+HAA!CG4+WANG!DQ4+PUNA!DQ4+GASA!CG4+GELA!DQ4+ZEMG!DQ4+TRON!DQ4+BUMA!DQ4+SARA!DQ4+TSIR!DQ4+DGNA!DQ4+PANG!DQ4+DPLA!DQ4+SJKA!DQ4+TRAG!CG4+MONA!AX4+LUNT!DQ4+TYSE!AX4+PEMA!AX4+KNLG!AX4+RJNG!AX4+WRMG!CG4+DUSM!AX4+GYPG!AX4+NGLM!CG4+SAMC!DQ4+PHUA!DQ4+TSMA!AX4+GEDU!CG4+SAMA!DQ4+TCHG!CG4+GMTU!DQ4+LHAM!AX4+PHLY!EX4 -> 4 | FE4: =PARO!AY4+HAA!CH4+WANG!DR4+PUNA!DR4+GASA!CH4+GELA!DR4+ZEMG!DR4+TRON!DR4+BUMA!DR4+SARA!DR4+TSIR!DR4+DGNA!DR4+PANG!DR4+DPLA!DR4+SJKA!DR4+TRAG!CH4+MONA!AY4+LUNT!DR4+TYSE!AY4+PEMA!AY4+KNLG!AY4+RJNG!AY4+WRMG!CH4+DUSM!AY4+GYPG!AY4+NGLM!CH4+SAMC!DR4+PHUA!DR4+TSMA!AY4+GEDU!CH4+SAMA!DR4+TCHG!CH4+GMTU!DR4+LHAM!AY4+PHLY!EY4 -> 0 | ... GA4: =PARO!BU4+HAA!DD4+WANG!EN4+PUNA!EN4+GASA!DD4+GELA!EN4+ZEMG!EN4+TRON!EN4+BUMA!EN4+SARA!EN4+TSIR!EN4+DGNA!EN4+PANG!EN4+DPLA!EN4+SJKA!EN4+TRAG!DD4+MONA!BU4+LUNT!EN4+TYSE!BU4+PEMA!BU4+KNLG!BU4+RJNG!BU4+WRMG!DD4+DUSM!BU4+GYPG!BU4+NGLM!DD4+SAMC!EN4+PHUA!EN4+TSMA!BU4+GEDU!DD4+SAMA!EN4+TCHG!DD4+GMTU!EN4+LHAM!BU4+PHLY!FU4 -> 0 | GB4: =PARO!BV4+HAA!DE4+WANG!EO4+PUNA!EO4+GASA!DE4+GELA!EO4+ZEMG!EO4+TRON!EO4+BUMA!EO4+SARA!EO4+TSIR!EO4+DGNA!EO4+PANG!EO4+DPLA!EO4+SJKA!EO4+TRAG!DE4+MONA!BW4+LUNT!EO4+TYSE!BW4+PEMA!BW4+KNLG!BW4+RJNG!BV4+WRMG!DE4+DUSM!BW4+GYPG!BW4+NGLM!DE4+SAMC!EO4+PHUA!EO4+TSMA!BV4+GEDU!DE4+SAMA!EO4+TCHG!DE4+GMTU!EO4+LHAM!BV4+PHLY!FV4 -> 23 | GC4: =PARO!BW4+HAA!DF4+WANG!EP4+PUNA!EP4+GASA!DF4+GELA!EP4+ZEMG!EP4+TRON!EP4+BUMA!EP4+SARA!EP4+TSIR!EP4+DGNA!EP4+PANG!EP4+DPLA!EP4+SJKA!EP4+TRAG!DF4+MONA!BX4+LUNT!EP4+TYSE!BX4+PEMA!BX4+KNLG!BX4+RJNG!BW4+WRMG!DF4+DUSM!BX4+GYPG!BX4+NGLM!DF4+SAMC!EP4+PHUA!EP4+TSMA!BW4+GEDU!DF4+SAMA!EP4+TCHG!DF4+GMTU!EP4+LHAM!BW4+PHLY!FW4 -> 8280 | GD4: =PARO!BX4+HAA!DG4+WANG!EQ4+PUNA!EQ4+GASA!DG4+GELA!EQ4+ZEMG!EQ4+TRON!EQ4+BUMA!EQ4+SARA!EQ4+TSIR!EQ4+DGNA!EQ4+PANG!EQ4+DPLA!EQ4+SJKA!EQ4+TRAG!DG4+MONA!BY4+LUNT!EQ4+TYSE!BY4+PEMA!BY4+KNLG!BY4+RJNG!BX4+WRMG!DG4+DUSM!BY4+GYPG!BY4+NGLM!DG4+SAMC!EQ4+PHUA!EQ4+TSMA!BX4+GEDU!DG4+SAMA!EQ4+TCHG!DG4+GMTU!EQ4+LHAM!BX4+PHLY!FX4 -> 1380 | GE4: =PARO!BY4+HAA!DH4+WANG!ER4+PUNA!ER4+GASA!DH4+GELA!ER4+ZEMG!ER4+TRON!ER4+BUMA!ER4+SARA!ER4+TSIR!ER4+DGNA!ER4+PANG!ER4+DPLA!ER4+SJKA!ER4+TRAG!DH4+MONA!BZ4+LUNT!ER4+TYSE!BZ4+PEMA!BZ4+KNLG!BZ4+RJNG!BY4+WRMG!DH4+DUSM!BZ4+GYPG!BZ4+NGLM!DH4+SAMC!ER4+PHUA!ER4+TSMA!BY4+GEDU!DH4+SAMA!ER4+TCHG!DH4+GMTU!ER4+LHAM!BY4+PHLY!FY4 -> 6900 | GG4: =PARO!CA4+HAA!DJ4+WANG!ET4+PUNA!ET4+GASA!DJ4+GELA!ET4+ZEMG!ET4+TRON!ET4+BUMA!ET4+SARA!ET4+TSIR!ET4+DGNA!ET4+PANG!ET4+DPLA!ET4+SJKA!ET4+TRAG!DJ4+MONA!CB4+LUNT!ET4+TYSE!CB4+PEMA!CB4+KNLG!CB4+RJNG!CA4+WRMG!DJ4+DUSM!CB4+GYPG!CB4+NGLM!DJ4+SAMC!ET4+PHUA!ET4+TSMA!CA4+GEDU!DJ4+SAMA!ET4+TCHG!DJ4+GMTU!ET4+LHAM!CA4+PHLY!GA4 -> 0 | GH4: =PARO!CB4+HAA!DK4+WANG!EU4+PUNA!EU4+GASA!DK4+GELA!EU4+ZEMG!EU4+TRON!EU4+BUMA!EU4+SARA!EU4+TSIR!EU4+DGNA!EU4+PANG!EU4+DPLA!EU4+SJKA!EU4+TRAG!DK4+MONA!CC4+LUNT!EU4+TYSE!CC4+PEMA!CC4+KNLG!CC4+RJNG!CB4+WRMG!DK4+DUSM!CC4+GYPG!CC4+NGLM!DK4+SAMC!EU4+PHUA!EU4+TSMA!CB4+GEDU!DK4+SAMA!EU4+TCHG!DK4+GMTU!EU4+LHAM!CB4+PHLY!GB4 -> 0 | GI4: =PARO!CC4+HAA!DL4+WANG!EV4+PUNA!EV4+GASA!DL4+GELA!EV4+ZEMG!EV4+TRON!EV4+BUMA!EV4+SARA!EV4+TSIR!EV4+DGNA!EV4+PANG!EV4+DPLA!EV4+SJKA!EV4+TRAG!DL4+MONA!CD4+LUNT!EV4+TYSE!CD4+PEMA!CD4+KNLG!CD4+RJNG!CC4+WRMG!DL4+DUSM!CD4+GYPG!CD4+NGLM!DL4+SAMC!EV4+PHUA!EV4+TSMA!CC4+GEDU!DL4+SAMA!EV4+TCHG!DL4+GMTU!EV4+LHAM!CC4+PHLY!GC4 -> 1 | GJ4: =PARO!CD4+HAA!DM4+WANG!EW4+PUNA!EW4+GASA!DM4+GELA!EW4+ZEMG!EW4+TRON!EW4+BUMA!EW4+SARA!EW4+TSIR!EW4+DGNA!EW4+PANG!EW4+DPLA!EW4+SJKA!EW4+TRAG!DM4+MONA!CE4+LUNT!EW4+TYSE!CE4+PEMA!CE4+KNLG!CE4+RJNG!CD4+WRMG!DM4+DUSM!CE4+GYPG!CE4+NGLM!DM4+SAMC!EW4+PHUA!EW4+TSMA!CD4+GEDU!DM4+SAMA!EW4+TCHG!DM4+GMTU!EW4+LHAM!CD4+PHLY!GD4 -> 0 | GK4: =PARO!CE4+HAA!DN4+WANG!EX4+PUNA!EX4+GASA!DN4+GELA!EX4+ZEMG!EX4+TRON!EX4+BUMA!EX4+SARA!EX4+TSIR!EX4+DGNA!EX4+PANG!EX4+DPLA!EX4+SJKA!EX4+TRAG!DN4+MONA!CF4+LUNT!EX4+TYSE!CF4+PEMA!CF4+KNLG!CF4+RJNG!CE4+WRMG!DN4+DUSM!CF4+GYPG!CF4+NGLM!DN4+SAMC!EX4+PHUA!EX4+TSMA!CE4+GEDU!DN4+SAMA!EX4+TCHG!DN4+GMTU!EX4+LHAM!CE4+PHLY!GE4 -> 0 | GL4: =PARO!CF4+HAA!DO4+WANG!EY4+PUNA!EY4+GASA!DO4+GELA!EY4+ZEMG!EY4+TRON!EY4+BUMA!EY4+SARA!EY4+TSIR!EY4+DGNA!EY4+PANG!EY4+DPLA!EY4+SJKA!EY4+TRAG!DO4+MONA!CG4+LUNT!EY4+TYSE!CG4+PEMA!CG4+KNLG!CG4+RJNG!CF4+WRMG!DO4+DUSM!CG4+GYPG!CG4+NGLM!DO4+SAMC!EY4+PHUA!EY4+TSMA!CF4+GEDU!DO4+SAMA!EY4+TCHG!DO4+GMTU!EY4+LHAM!CF4+PHLY!GF4 -> 0 | GM4: =PARO!CG4+HAA!DP4+WANG!EZ4+PUNA!EZ4+GASA!DP4+GELA!EZ4+ZEMG!EZ4+TRON!EZ4+BUMA!EZ4+SARA!EZ4+TSIR!EZ4+DGNA!EZ4+PANG!EZ4+DPLA!EZ4+SJKA!EZ4+TRAG!DP4+MONA!CH4+LUNT!EZ4+TYSE!CH4+PEMA!CH4+KNLG!CH4+RJNG!CG4+WRMG!DP4+DUSM!CH4+GYPG!CH4+NGLM!DP4+SAMC!EZ4+PHUA!EZ4+TSMA!CG4+GEDU!DP4+SAMA!EZ4+TCHG!DP4+GMTU!EZ4+LHAM!CG4+PHLY!GG4 -> 0 | GN4: =PARO!CH4+HAA!DQ4+WANG!FA4+PUNA!FA4+GASA!DQ4+GELA!FA4+ZEMG!FA4+TRON!FA4+BUMA!FA4+SARA!FA4+TSIR!FA4+DGNA!FA4+PANG!FA4+DPLA!FA4+SJKA!FA4+TRAG!DQ4+MONA!CI4+LUNT!FA4+TYSE!CI4+PEMA!CI4+KNLG!CI4+RJNG!CH4+WRMG!DQ4+DUSM!CI4+GYPG!CI4+NGLM!DQ4+SAMC!FA4+PHUA!FA4+TSMA!CH4+GEDU!DQ4+SAMA!FA4+TCHG!DQ4+GMTU!FA4+LHAM!CH4+PHLY!GH4 -> 0 | ... HO4: =PARO!DI4+HAA!ER4+WANG!GB4+PUNA!GB4+GASA!ER4+GELA!GB4+ZEMG!GB4+TRON!GB4+BUMA!GB4+SARA!GB4+TSIR!GB4+DGNA!GB4+PANG!GB4+DPLA!GB4+SJKA!GB4+TRAG!ER4+MONA!DJ4+LUNT!GB4+TYSE!DJ4+PEMA!DJ4+KNLG!DJ4+RJNG!DI4+WRMG!ER4+DUSM!DJ4+GYPG!DJ4+NGLM!ER4+SAMC!GB4+PHUA!GB4+TSMA!DI4+GEDU!ER4+SAMA!GB4+TCHG!ER4+GMTU!GB4+LHAM!DI4+PHLY!HI4 -> 2400 | HQ4: =ES4+GB4+HL4 -> 59 | HR4: =C4*HQ4 -> 17700 | HS4: =D4*HQ4 -> 21240 | HT4: =E4*HQ4 -> 3540 | HU4: 30 | HV4: =HQ4*HU4 -> 1770 | IN4: =AJ4+BT4+DC4+ES4+GB4+HL4 -> 150 | IO4: =AK4+BU4+DD4+ET4+GC4+HM4 -> 54000 | IP4: =AL4+BV4+DE4+EU4+GD4+HN4 -> 9000 | IQ4: =AM4+BW4+DF4+EV4+GE4+HO4 -> 45000 | IR4: =IR3/80 -> 7.075
A5: 3 | B5: Tumeric and Cinnamon tea | C5: 300 | D5: 360 | E5: =D5-C5 -> 60 | H5: =PHLY!H5 -> 0 | I5: =PHLY!I5 -> 0 | J5: =PHLY!J5 -> 0 | K5: =PHLY!K5 -> 0 | L5: =PHLY!L5 -> 0 | M5: =PHLY!M5 -> 0 | N5: =PHLY!N5 -> 0 | O5: =PHLY!O5 -> 0 | ... AM5: =PHLY!AM5 -> 0 | AO5: =WANG!H5+PUNA!H5+GELA!H5+ZEMG!H5+TRON!H5+BUMA!H5+SARA!H5+TSIR!H5+DGNA!H5+PANG!H5+DPLA!H5+SJKA!H5+LUNT!H5+SAMC!H5+PHUA!H5+SAMA!H5+GMTU!H5+PHLY!AO5 -> 0 | AP5: =WANG!I5+PUNA!I5+GELA!I5+ZEMG!I5+TRON!I5+BUMA!I5+SARA!I5+TSIR!I5+DGNA!I5+PANG!I5+DPLA!I5+SJKA!I5+LUNT!I5+SAMC!I5+PHUA!I5+SAMA!I5+GMTU!I5+PHLY!AP5 -> 0 | AQ5: =WANG!J5+PUNA!J5+GELA!J5+ZEMG!J5+TRON!J5+BUMA!J5+SARA!J5+TSIR!J5+DGNA!J5+PANG!J5+DPLA!J5+SJKA!J5+LUNT!J5+SAMC!J5+PHUA!J5+SAMA!J5+GMTU!J5+PHLY!AQ5 -> 0 | AR5: =WANG!K5+PUNA!K5+GELA!K5+ZEMG!K5+TRON!K5+BUMA!K5+SARA!K5+TSIR!K5+DGNA!K5+PANG!K5+DPLA!K5+SJKA!K5+LUNT!K5+SAMC!K5+PHUA!K5+SAMA!K5+GMTU!K5+PHLY!AR5 -> 0 | AS5: =WANG!L5+PUNA!L5+GELA!L5+ZEMG!L5+TRON!L5+BUMA!L5+SARA!L5+TSIR!L5+DGNA!L5+PANG!L5+DPLA!L5+SJKA!L5+LUNT!L5+SAMC!L5+PHUA!L5+SAMA!L5+GMTU!L5+PHLY!AS5 -> 2 | AT5: =WANG!M5+PUNA!M5+GELA!M5+ZEMG!M5+TRON!M5+BUMA!M5+SARA!M5+TSIR!M5+DGNA!M5+PANG!M5+DPLA!M5+SJKA!M5+LUNT!M5+SAMC!M5+PHUA!M5+SAMA!M5+GMTU!M5+PHLY!AT5 -> 0 | AU5: =WANG!N5+PUNA!N5+GELA!N5+ZEMG!N5+TRON!N5+BUMA!N5+SARA!N5+TSIR!N5+DGNA!N5+PANG!N5+DPLA!N5+SJKA!N5+LUNT!N5+SAMC!N5+PHUA!N5+SAMA!N5+GMTU!N5+PHLY!AU5 -> 3 | AV5: =WANG!O5+PUNA!O5+GELA!O5+ZEMG!O5+TRON!O5+BUMA!O5+SARA!O5+TSIR!O5+DGNA!O5+PANG!O5+DPLA!O5+SJKA!O5+LUNT!O5+SAMC!O5+PHUA!O5+SAMA!O5+GMTU!O5+PHLY!AV5 -> 0 | ... BW5: =WANG!AP5+PUNA!AP5+GELA!AP5+ZEMG!AP5+TRON!AP5+BUMA!AP5+SARA!AP5+TSIR!AP5+DGNA!AP5+PANG!AP5+DPLA!AP5+SJKA!AP5+LUNT!AP5+SAMC!AP5+PHUA!AP5+SAMA!AP5+GMTU!AP5+PHLY!BW5 -> 10800 | BY5: =HAA!H5+WANG!AR5+PUNA!AR5+GASA!H5+GELA!AR5+ZEMG!AR5+TRON!AR5+BUMA!AR5+SARA!AR5+TSIR!AR5+DGNA!AR5+PANG!AR5+DPLA!AR5+SJKA!AR5+TRAG!H5+LUNT!AR5+WRMG!H5+NGLM!H5+SAMC!AR5+PHUA!AR5+GEDU!H5+SAMA!AR5+TCHG!H5+GMTU!AR5+PHLY!BY5 -> 3 | BZ5: =HAA!I5+WANG!AS5+PUNA!AS5+GASA!I5+GELA!AS5+ZEMG!AS5+TRON!AS5+BUMA!AS5+SARA!AS5+TSIR!AS5+DGNA!AS5+PANG!AS5+DPLA!AS5+SJKA!AS5+TRAG!I5+LUNT!AS5+WRMG!I5+NGLM!I5+SAMC!AS5+PHUA!AS5+GEDU!I5+SAMA!AS5+TCHG!I5+GMTU!AS5+PHLY!BZ5 -> 4 | CA5: =HAA!J5+WANG!AT5+PUNA!AT5+GASA!J5+GELA!AT5+ZEMG!AT5+TRON!AT5+BUMA!AT5+SARA!AT5+TSIR!AT5+DGNA!AT5+PANG!AT5+DPLA!AT5+SJKA!AT5+TRAG!J5+LUNT!AT5+WRMG!J5+NGLM!J5+SAMC!AT5+PHUA!AT5+GEDU!J5+SAMA!AT5+TCHG!J5+GMTU!AT5+PHLY!CA5 -> 3 | CB5: =HAA!K5+WANG!AU5+PUNA!AU5+GASA!K5+GELA!AU5+ZEMG!AU5+TRON!AU5+BUMA!AU5+SARA!AU5+TSIR!AU5+DGNA!AU5+PANG!AU5+DPLA!AU5+SJKA!AU5+TRAG!K5+LUNT!AU5+WRMG!K5+NGLM!K5+SAMC!AU5+PHUA!AU5+GEDU!K5+SAMA!AU5+TCHG!K5+GMTU!AU5+PHLY!CB5 -> 2 | CC5: =HAA!L5+WANG!AV5+PUNA!AV5+GASA!L5+GELA!AV5+ZEMG!AV5+TRON!AV5+BUMA!AV5+SARA!AV5+TSIR!AV5+DGNA!AV5+PANG!AV5+DPLA!AV5+SJKA!AV5+TRAG!L5+LUNT!AV5+WRMG!L5+NGLM!L5+SAMC!AV5+PHUA!AV5+GEDU!L5+SAMA!AV5+TCHG!L5+GMTU!AV5+PHLY!CC5 -> 0 | CD5: =HAA!M5+WANG!AW5+PUNA!AW5+GASA!M5+GELA!AW5+ZEMG!AW5+TRON!AW5+BUMA!AW5+SARA!AW5+TSIR!AW5+DGNA!AW5+PANG!AW5+DPLA!AW5+SJKA!AW5+TRAG!M5+LUNT!AW5+WRMG!M5+NGLM!M5+SAMC!AW5+PHUA!AW5+GEDU!M5+SAMA!AW5+TCHG!M5+GMTU!AW5+PHLY!CD5 -> 0 | CE5: =HAA!N5+WANG!AX5+PUNA!AX5+GASA!N5+GELA!AX5+ZEMG!AX5+TRON!AX5+BUMA!AX5+SARA!AX5+TSIR!AX5+DGNA!AX5+PANG!AX5+DPLA!AX5+SJKA!AX5+TRAG!N5+LUNT!AX5+WRMG!N5+NGLM!N5+SAMC!AX5+PHUA!AX5+GEDU!N5+SAMA!AX5+TCHG!N5+GMTU!AX5+PHLY!CE5 -> 1 | CF5: =HAA!O5+WANG!AY5+PUNA!AY5+GASA!O5+GELA!AY5+ZEMG!AY5+TRON!AY5+BUMA!AY5+SARA!AY5+TSIR!AY5+DGNA!AY5+PANG!AY5+DPLA!AY5+SJKA!AY5+TRAG!O5+LUNT!AY5+WRMG!O5+NGLM!O5+SAMC!AY5+PHUA!AY5+GEDU!O5+SAMA!AY5+TCHG!O5+GMTU!AY5+PHLY!CF5 -> 0 | ... DF5: =HAA!AO5+WANG!BY5+PUNA!BY5+GASA!AO5+GELA!BY5+ZEMG!BY5+TRON!BY5+BUMA!BY5+SARA!BY5+TSIR!BY5+DGNA!BY5+PANG!BY5+DPLA!BY5+SJKA!BY5+TRAG!AO5+LUNT!BY5+WRMG!AO5+NGLM!AO5+SAMC!BY5+PHUA!BY5+GEDU!AO5+SAMA!BY5+TCHG!AO5+GMTU!BY5+PHLY!DF5 -> 21000 | DG5: =AJ5+BT5+DC5 -> 106 | DH5: =C5*DG5 -> 31800 | DI5: =D5*DG5 -> 38160 | DJ5: =E5*DG5 -> 6360 | DK5: 30 | DL5: =DG5*DK5 -> 3180 | DN5: =PARO!H5+HAA!AQ5+WANG!CA5+PUNA!CA5+GASA!AQ5+GELA!CA5+ZEMG!CA5+TRON!CA5+BUMA!CA5+SARA!CA5+TSIR!CA5+DGNA!CA5+PANG!CA5+DPLA!CA5+SJKA!CA5+TRAG!AQ5+MONA!H5+LUNT!CA5+TYSE!H5+PEMA!H5+KNLG!H5+RJNG!H5+WRMG!AQ5+DUSM!H5+GYPG!H5+NGLM!AQ5+SAMC!CA5+PHUA!CA5+TSMA!H5+GEDU!AQ5+SAMA!CA5+TCHG!AQ5+GMTU!CA5+LHAM!H5+PHLY!DH5 -> 1 | DO5: =PARO!I5+HAA!AR5+WANG!CB5+PUNA!CB5+GASA!AR5+GELA!CB5+ZEMG!CB5+TRON!CB5+BUMA!CB5+SARA!CB5+TSIR!CB5+DGNA!CB5+PANG!CB5+DPLA!CB5+SJKA!CB5+TRAG!AR5+MONA!I5+LUNT!CB5+TYSE!I5+PEMA!I5+KNLG!I5+RJNG!I5+WRMG!AR5+DUSM!I5+GYPG!I5+NGLM!AR5+SAMC!CB5+PHUA!CB5+TSMA!I5+GEDU!AR5+SAMA!CB5+TCHG!AR5+GMTU!CB5+LHAM!I5+PHLY!DI5 -> 0 | DP5: =PARO!J5+HAA!AS5+WANG!CC5+PUNA!CC5+GASA!AS5+GELA!CC5+ZEMG!CC5+TRON!CC5+BUMA!CC5+SARA!CC5+TSIR!CC5+DGNA!CC5+PANG!CC5+DPLA!CC5+SJKA!CC5+TRAG!AS5+MONA!J5+LUNT!CC5+TYSE!J5+PEMA!J5+KNLG!J5+RJNG!J5+WRMG!AS5+DUSM!J5+GYPG!J5+NGLM!AS5+SAMC!CC5+PHUA!CC5+TSMA!J5+GEDU!AS5+SAMA!CC5+TCHG!AS5+GMTU!CC5+LHAM!J5+PHLY!DJ5 -> 0 | DQ5: =PARO!K5+HAA!AT5+WANG!CD5+PUNA!CD5+GASA!AT5+GELA!CD5+ZEMG!CD5+TRON!CD5+BUMA!CD5+SARA!CD5+TSIR!CD5+DGNA!CD5+PANG!CD5+DPLA!CD5+SJKA!CD5+TRAG!AT5+MONA!K5+LUNT!CD5+TYSE!K5+PEMA!K5+KNLG!K5+RJNG!K5+WRMG!AT5+DUSM!K5+GYPG!K5+NGLM!AT5+SAMC!CD5+PHUA!CD5+TSMA!K5+GEDU!AT5+SAMA!CD5+TCHG!AT5+GMTU!CD5+LHAM!K5+PHLY!DK5 -> 0 | DR5: =PARO!L5+HAA!AU5+WANG!CE5+PUNA!CE5+GASA!AU5+GELA!CE5+ZEMG!CE5+TRON!CE5+BUMA!CE5+SARA!CE5+TSIR!CE5+DGNA!CE5+PANG!CE5+DPLA!CE5+SJKA!CE5+TRAG!AU5+MONA!L5+LUNT!CE5+TYSE!L5+PEMA!L5+KNLG!L5+RJNG!L5+WRMG!AU5+DUSM!L5+GYPG!L5+NGLM!AU5+SAMC!CE5+PHUA!CE5+TSMA!L5+GEDU!AU5+SAMA!CE5+TCHG!AU5+GMTU!CE5+LHAM!L5+PHLY!DL5 -> 1 | DS5: =PARO!M5+HAA!AV5+WANG!CF5+PUNA!CF5+GASA!AV5+GELA!CF5+ZEMG!CF5+TRON!CF5+BUMA!CF5+SARA!CF5+TSIR!CF5+DGNA!CF5+PANG!CF5+DPLA!CF5+SJKA!CF5+TRAG!AV5+MONA!M5+LUNT!CF5+TYSE!M5+PEMA!M5+KNLG!M5+RJNG!M5+WRMG!AV5+DUSM!M5+GYPG!M5+NGLM!AV5+SAMC!CF5+PHUA!CF5+TSMA!M5+GEDU!AV5+SAMA!CF5+TCHG!AV5+GMTU!CF5+LHAM!M5+PHLY!DM5 -> 15 | DT5: =PARO!N5+HAA!AW5+WANG!CG5+PUNA!CG5+GASA!AW5+GELA!CG5+ZEMG!CG5+TRON!CG5+BUMA!CG5+SARA!CG5+TSIR!CG5+DGNA!CG5+PANG!CG5+DPLA!CG5+SJKA!CG5+TRAG!AW5+MONA!N5+LUNT!CG5+TYSE!N5+PEMA!N5+KNLG!N5+RJNG!N5+WRMG!AW5+DUSM!N5+GYPG!N5+NGLM!AW5+SAMC!CG5+PHUA!CG5+TSMA!N5+GEDU!AW5+SAMA!CG5+TCHG!AW5+GMTU!CG5+LHAM!N5+PHLY!DN5 -> 1 | DU5: =PARO!O5+HAA!AX5+WANG!CH5+PUNA!CH5+GASA!AX5+GELA!CH5+ZEMG!CH5+TRON!CH5+BUMA!CH5+SARA!CH5+TSIR!CH5+DGNA!CH5+PANG!CH5+DPLA!CH5+SJKA!CH5+TRAG!AX5+MONA!O5+LUNT!CH5+TYSE!O5+PEMA!O5+KNLG!O5+RJNG!O5+WRMG!AX5+DUSM!O5+GYPG!O5+NGLM!AX5+SAMC!CH5+PHUA!CH5+TSMA!O5+GEDU!AX5+SAMA!CH5+TCHG!AX5+GMTU!CH5+LHAM!O5+PHLY!DO5 -> 0 | ... EV5: =PARO!AP5+HAA!BY5+WANG!DI5+PUNA!DI5+GASA!BY5+GELA!DI5+ZEMG!DI5+TRON!DI5+BUMA!DI5+SARA!DI5+TSIR!DI5+DGNA!DI5+PANG!DI5+DPLA!DI5+SJKA!DI5+TRAG!BY5+MONA!AP5+LUNT!DI5+TYSE!AP5+PEMA!AP5+KNLG!AP5+RJNG!AP5+WRMG!BY5+DUSM!AP5+GYPG!AP5+NGLM!BY5+SAMC!DI5+PHUA!DI5+TSMA!AP5+GEDU!BY5+SAMA!DI5+TCHG!BY5+GMTU!DI5+LHAM!AP5+PHLY!EP5 -> 12000 | EX5: =PARO!AR5+HAA!CA5+WANG!DK5+PUNA!DK5+GASA!CA5+GELA!DK5+ZEMG!DK5+TRON!DK5+BUMA!DK5+SARA!DK5+TSIR!DK5+DGNA!DK5+PANG!DK5+DPLA!DK5+SJKA!DK5+TRAG!CA5+MONA!AR5+LUNT!DK5+TYSE!AR5+PEMA!AR5+KNLG!AR5+RJNG!AR5+WRMG!CA5+DUSM!AR5+GYPG!AR5+NGLM!CA5+SAMC!DK5+PHUA!DK5+TSMA!AR5+GEDU!CA5+SAMA!DK5+TCHG!CA5+GMTU!DK5+LHAM!AR5+PHLY!ER5 -> 0 | EY5: =PARO!AS5+HAA!CB5+WANG!DL5+PUNA!DL5+GASA!CB5+GELA!DL5+ZEMG!DL5+TRON!DL5+BUMA!DL5+SARA!DL5+TSIR!DL5+DGNA!DL5+PANG!DL5+DPLA!DL5+SJKA!DL5+TRAG!CB5+MONA!AS5+LUNT!DL5+TYSE!AS5+PEMA!AS5+KNLG!AS5+RJNG!AS5+WRMG!CB5+DUSM!AS5+GYPG!AS5+NGLM!CB5+SAMC!DL5+PHUA!DL5+TSMA!AS5+GEDU!CB5+SAMA!DL5+TCHG!CB5+GMTU!DL5+LHAM!AS5+PHLY!ES5 -> 0 | EZ5: =PARO!AT5+HAA!CC5+WANG!DM5+PUNA!DM5+GASA!CC5+GELA!DM5+ZEMG!DM5+TRON!DM5+BUMA!DM5+SARA!DM5+TSIR!DM5+DGNA!DM5+PANG!DM5+DPLA!DM5+SJKA!DM5+TRAG!CC5+MONA!AT5+LUNT!DM5+TYSE!AT5+PEMA!AT5+KNLG!AT5+RJNG!AT5+WRMG!CC5+DUSM!AT5+GYPG!AT5+NGLM!CC5+SAMC!DM5+PHUA!DM5+TSMA!AT5+GEDU!CC5+SAMA!DM5+TCHG!CC5+GMTU!DM5+LHAM!AT5+PHLY!ET5 -> 1 | FA5: =PARO!AU5+HAA!CD5+WANG!DN5+PUNA!DN5+GASA!CD5+GELA!DN5+ZEMG!DN5+TRON!DN5+BUMA!DN5+SARA!DN5+TSIR!DN5+DGNA!DN5+PANG!DN5+DPLA!DN5+SJKA!DN5+TRAG!CD5+MONA!AU5+LUNT!DN5+TYSE!AU5+PEMA!AU5+KNLG!AU5+RJNG!AU5+WRMG!CD5+DUSM!AU5+GYPG!AU5+NGLM!CD5+SAMC!DN5+PHUA!DN5+TSMA!AU5+GEDU!CD5+SAMA!DN5+TCHG!CD5+GMTU!DN5+LHAM!AU5+PHLY!EU5 -> 3 | FB5: =PARO!AV5+HAA!CE5+WANG!DO5+PUNA!DO5+GASA!CE5+GELA!DO5+ZEMG!DO5+TRON!DO5+BUMA!DO5+SARA!DO5+TSIR!DO5+DGNA!DO5+PANG!DO5+DPLA!DO5+SJKA!DO5+TRAG!CE5+MONA!AV5+LUNT!DO5+TYSE!AV5+PEMA!AV5+KNLG!AV5+RJNG!AV5+WRMG!CE5+DUSM!AV5+GYPG!AV5+NGLM!CE5+SAMC!DO5+PHUA!DO5+TSMA!AV5+GEDU!CE5+SAMA!DO5+TCHG!CE5+GMTU!DO5+LHAM!AV5+PHLY!EV5 -> 2 | FC5: =PARO!AW5+HAA!CF5+WANG!DP5+PUNA!DP5+GASA!CF5+GELA!DP5+ZEMG!DP5+TRON!DP5+BUMA!DP5+SARA!DP5+TSIR!DP5+DGNA!DP5+PANG!DP5+DPLA!DP5+SJKA!DP5+TRAG!CF5+MONA!AW5+LUNT!DP5+TYSE!AW5+PEMA!AW5+KNLG!AW5+RJNG!AW5+WRMG!CF5+DUSM!AW5+GYPG!AW5+NGLM!CF5+SAMC!DP5+PHUA!DP5+TSMA!AW5+GEDU!CF5+SAMA!DP5+TCHG!CF5+GMTU!DP5+LHAM!AW5+PHLY!EW5 -> 1 | FD5: =PARO!AX5+HAA!CG5+WANG!DQ5+PUNA!DQ5+GASA!CG5+GELA!DQ5+ZEMG!DQ5+TRON!DQ5+BUMA!DQ5+SARA!DQ5+TSIR!DQ5+DGNA!DQ5+PANG!DQ5+DPLA!DQ5+SJKA!DQ5+TRAG!CG5+MONA!AX5+LUNT!DQ5+TYSE!AX5+PEMA!AX5+KNLG!AX5+RJNG!AX5+WRMG!CG5+DUSM!AX5+GYPG!AX5+NGLM!CG5+SAMC!DQ5+PHUA!DQ5+TSMA!AX5+GEDU!CG5+SAMA!DQ5+TCHG!CG5+GMTU!DQ5+LHAM!AX5+PHLY!EX5 -> 2 | FE5: =PARO!AY5+HAA!CH5+WANG!DR5+PUNA!DR5+GASA!CH5+GELA!DR5+ZEMG!DR5+TRON!DR5+BUMA!DR5+SARA!DR5+TSIR!DR5+DGNA!DR5+PANG!DR5+DPLA!DR5+SJKA!DR5+TRAG!CH5+MONA!AY5+LUNT!DR5+TYSE!AY5+PEMA!AY5+KNLG!AY5+RJNG!AY5+WRMG!CH5+DUSM!AY5+GYPG!AY5+NGLM!CH5+SAMC!DR5+PHUA!DR5+TSMA!AY5+GEDU!CH5+SAMA!DR5+TCHG!CH5+GMTU!DR5+LHAM!AY5+PHLY!EY5 -> 0 | ... GA5: =PARO!BU5+HAA!DD5+WANG!EN5+PUNA!EN5+GASA!DD5+GELA!EN5+ZEMG!EN5+TRON!EN5+BUMA!EN5+SARA!EN5+TSIR!EN5+DGNA!EN5+PANG!EN5+DPLA!EN5+SJKA!EN5+TRAG!DD5+MONA!BU5+LUNT!EN5+TYSE!BU5+PEMA!BU5+KNLG!BU5+RJNG!BU5+WRMG!DD5+DUSM!BU5+GYPG!BU5+NGLM!DD5+SAMC!EN5+PHUA!EN5+TSMA!BU5+GEDU!DD5+SAMA!EN5+TCHG!DD5+GMTU!EN5+LHAM!BU5+PHLY!FU5 -> 0 | GB5: =PARO!BV5+HAA!DE5+WANG!EO5+PUNA!EO5+GASA!DE5+GELA!EO5+ZEMG!EO5+TRON!EO5+BUMA!EO5+SARA!EO5+TSIR!EO5+DGNA!EO5+PANG!EO5+DPLA!EO5+SJKA!EO5+TRAG!DE5+MONA!BW5+LUNT!EO5+TYSE!BW5+PEMA!BW5+KNLG!BW5+RJNG!BV5+WRMG!DE5+DUSM!BW5+GYPG!BW5+NGLM!DE5+SAMC!EO5+PHUA!EO5+TSMA!BV5+GEDU!DE5+SAMA!EO5+TCHG!DE5+GMTU!EO5+LHAM!BV5+PHLY!FV5 -> 17 | GC5: =PARO!BW5+HAA!DF5+WANG!EP5+PUNA!EP5+GASA!DF5+GELA!EP5+ZEMG!EP5+TRON!EP5+BUMA!EP5+SARA!EP5+TSIR!EP5+DGNA!EP5+PANG!EP5+DPLA!EP5+SJKA!EP5+TRAG!DF5+MONA!BX5+LUNT!EP5+TYSE!BX5+PEMA!BX5+KNLG!BX5+RJNG!BW5+WRMG!DF5+DUSM!BX5+GYPG!BX5+NGLM!DF5+SAMC!EP5+PHUA!EP5+TSMA!BW5+GEDU!DF5+SAMA!EP5+TCHG!DF5+GMTU!EP5+LHAM!BW5+PHLY!FW5 -> 6120 | GD5: =PARO!BX5+HAA!DG5+WANG!EQ5+PUNA!EQ5+GASA!DG5+GELA!EQ5+ZEMG!EQ5+TRON!EQ5+BUMA!EQ5+SARA!EQ5+TSIR!EQ5+DGNA!EQ5+PANG!EQ5+DPLA!EQ5+SJKA!EQ5+TRAG!DG5+MONA!BY5+LUNT!EQ5+TYSE!BY5+PEMA!BY5+KNLG!BY5+RJNG!BX5+WRMG!DG5+DUSM!BY5+GYPG!BY5+NGLM!DG5+SAMC!EQ5+PHUA!EQ5+TSMA!BX5+GEDU!DG5+SAMA!EQ5+TCHG!DG5+GMTU!EQ5+LHAM!BX5+PHLY!FX5 -> 1020 | GE5: =PARO!BY5+HAA!DH5+WANG!ER5+PUNA!ER5+GASA!DH5+GELA!ER5+ZEMG!ER5+TRON!ER5+BUMA!ER5+SARA!ER5+TSIR!ER5+DGNA!ER5+PANG!ER5+DPLA!ER5+SJKA!ER5+TRAG!DH5+MONA!BZ5+LUNT!ER5+TYSE!BZ5+PEMA!BZ5+KNLG!BZ5+RJNG!BY5+WRMG!DH5+DUSM!BZ5+GYPG!BZ5+NGLM!DH5+SAMC!ER5+PHUA!ER5+TSMA!BY5+GEDU!DH5+SAMA!ER5+TCHG!DH5+GMTU!ER5+LHAM!BY5+PHLY!FY5 -> 5100 | GG5: =PARO!CA5+HAA!DJ5+WANG!ET5+PUNA!ET5+GASA!DJ5+GELA!ET5+ZEMG!ET5+TRON!ET5+BUMA!ET5+SARA!ET5+TSIR!ET5+DGNA!ET5+PANG!ET5+DPLA!ET5+SJKA!ET5+TRAG!DJ5+MONA!CB5+LUNT!ET5+TYSE!CB5+PEMA!CB5+KNLG!CB5+RJNG!CA5+WRMG!DJ5+DUSM!CB5+GYPG!CB5+NGLM!DJ5+SAMC!ET5+PHUA!ET5+TSMA!CA5+GEDU!DJ5+SAMA!ET5+TCHG!DJ5+GMTU!ET5+LHAM!CA5+PHLY!GA5 -> 0 | GH5: =PARO!CB5+HAA!DK5+WANG!EU5+PUNA!EU5+GASA!DK5+GELA!EU5+ZEMG!EU5+TRON!EU5+BUMA!EU5+SARA!EU5+TSIR!EU5+DGNA!EU5+PANG!EU5+DPLA!EU5+SJKA!EU5+TRAG!DK5+MONA!CC5+LUNT!EU5+TYSE!CC5+PEMA!CC5+KNLG!CC5+RJNG!CB5+WRMG!DK5+DUSM!CC5+GYPG!CC5+NGLM!DK5+SAMC!EU5+PHUA!EU5+TSMA!CB5+GEDU!DK5+SAMA!EU5+TCHG!DK5+GMTU!EU5+LHAM!CB5+PHLY!GB5 -> 0 | GI5: =PARO!CC5+HAA!DL5+WANG!EV5+PUNA!EV5+GASA!DL5+GELA!EV5+ZEMG!EV5+TRON!EV5+BUMA!EV5+SARA!EV5+TSIR!EV5+DGNA!EV5+PANG!EV5+DPLA!EV5+SJKA!EV5+TRAG!DL5+MONA!CD5+LUNT!EV5+TYSE!CD5+PEMA!CD5+KNLG!CD5+RJNG!CC5+WRMG!DL5+DUSM!CD5+GYPG!CD5+NGLM!DL5+SAMC!EV5+PHUA!EV5+TSMA!CC5+GEDU!DL5+SAMA!EV5+TCHG!DL5+GMTU!EV5+LHAM!CC5+PHLY!GC5 -> 0 | GJ5: =PARO!CD5+HAA!DM5+WANG!EW5+PUNA!EW5+GASA!DM5+GELA!EW5+ZEMG!EW5+TRON!EW5+BUMA!EW5+SARA!EW5+TSIR!EW5+DGNA!EW5+PANG!EW5+DPLA!EW5+SJKA!EW5+TRAG!DM5+MONA!CE5+LUNT!EW5+TYSE!CE5+PEMA!CE5+KNLG!CE5+RJNG!CD5+WRMG!DM5+DUSM!CE5+GYPG!CE5+NGLM!DM5+SAMC!EW5+PHUA!EW5+TSMA!CD5+GEDU!DM5+SAMA!EW5+TCHG!DM5+GMTU!EW5+LHAM!CD5+PHLY!GD5 -> 8 | GK5: =PARO!CE5+HAA!DN5+WANG!EX5+PUNA!EX5+GASA!DN5+GELA!EX5+ZEMG!EX5+TRON!EX5+BUMA!EX5+SARA!EX5+TSIR!EX5+DGNA!EX5+PANG!EX5+DPLA!EX5+SJKA!EX5+TRAG!DN5+MONA!CF5+LUNT!EX5+TYSE!CF5+PEMA!CF5+KNLG!CF5+RJNG!CE5+WRMG!DN5+DUSM!CF5+GYPG!CF5+NGLM!DN5+SAMC!EX5+PHUA!EX5+TSMA!CE5+GEDU!DN5+SAMA!EX5+TCHG!DN5+GMTU!EX5+LHAM!CE5+PHLY!GE5 -> 0 | GL5: =PARO!CF5+HAA!DO5+WANG!EY5+PUNA!EY5+GASA!DO5+GELA!EY5+ZEMG!EY5+TRON!EY5+BUMA!EY5+SARA!EY5+TSIR!EY5+DGNA!EY5+PANG!EY5+DPLA!EY5+SJKA!EY5+TRAG!DO5+MONA!CG5+LUNT!EY5+TYSE!CG5+PEMA!CG5+KNLG!CG5+RJNG!CF5+WRMG!DO5+DUSM!CG5+GYPG!CG5+NGLM!DO5+SAMC!EY5+PHUA!EY5+TSMA!CF5+GEDU!DO5+SAMA!EY5+TCHG!DO5+GMTU!EY5+LHAM!CF5+PHLY!GF5 -> 0 | GM5: =PARO!CG5+HAA!DP5+WANG!EZ5+PUNA!EZ5+GASA!DP5+GELA!EZ5+ZEMG!EZ5+TRON!EZ5+BUMA!EZ5+SARA!EZ5+TSIR!EZ5+DGNA!EZ5+PANG!EZ5+DPLA!EZ5+SJKA!EZ5+TRAG!DP5+MONA!CH5+LUNT!EZ5+TYSE!CH5+PEMA!CH5+KNLG!CH5+RJNG!CG5+WRMG!DP5+DUSM!CH5+GYPG!CH5+NGLM!DP5+SAMC!EZ5+PHUA!EZ5+TSMA!CG5+GEDU!DP5+SAMA!EZ5+TCHG!DP5+GMTU!EZ5+LHAM!CG5+PHLY!GG5 -> 1 | GN5: =PARO!CH5+HAA!DQ5+WANG!FA5+PUNA!FA5+GASA!DQ5+GELA!FA5+ZEMG!FA5+TRON!FA5+BUMA!FA5+SARA!FA5+TSIR!FA5+DGNA!FA5+PANG!FA5+DPLA!FA5+SJKA!FA5+TRAG!DQ5+MONA!CI5+LUNT!FA5+TYSE!CI5+PEMA!CI5+KNLG!CI5+RJNG!CH5+WRMG!DQ5+DUSM!CI5+GYPG!CI5+NGLM!DQ5+SAMC!FA5+PHUA!FA5+TSMA!CH5+GEDU!DQ5+SAMA!FA5+TCHG!DQ5+GMTU!FA5+LHAM!CH5+PHLY!GH5 -> 0 | ... HO5: =PARO!DI5+HAA!ER5+WANG!GB5+PUNA!GB5+GASA!ER5+GELA!GB5+ZEMG!GB5+TRON!GB5+BUMA!GB5+SARA!GB5+TSIR!GB5+DGNA!GB5+PANG!GB5+DPLA!GB5+SJKA!GB5+TRAG!ER5+MONA!DJ5+LUNT!GB5+TYSE!DJ5+PEMA!DJ5+KNLG!DJ5+RJNG!DI5+WRMG!ER5+DUSM!DJ5+GYPG!DJ5+NGLM!ER5+SAMC!GB5+PHUA!GB5+TSMA!DI5+GEDU!ER5+SAMA!GB5+TCHG!ER5+GMTU!GB5+LHAM!DI5+PHLY!HI5 -> 6900 | HQ5: =ES5+GB5+HL5 -> 80 | HR5: =C5*HQ5 -> 24000 | HS5: =D5*HQ5 -> 28800 | HT5: =E5*HQ5 -> 4800 | HU5: 30 | HV5: =HQ5*HU5 -> 2400 | IN5: =AJ5+BT5+DC5+ES5+GB5+HL5 -> 186 | IO5: =AK5+BU5+DD5+ET5+GC5+HM5 -> 66960 | IP5: =AL5+BV5+DE5+EU5+GD5+HN5 -> 11160 | IQ5: =AM5+BW5+DF5+EV5+GE5+HO5 -> 55800
A6: 4 | B6: Cordyceps Happiness Tea | C6: 995 | D6: 1194 | E6: =D6-C6 -> 199 | F6: No Discount | H6: =PHLY!H6 -> 0 | I6: =PHLY!I6 -> 0 | J6: =PHLY!J6 -> 0 | K6: =PHLY!K6 -> 0 | L6: =PHLY!L6 -> 0 | M6: =PHLY!M6 -> 0 | N6: =PHLY!N6 -> 0 | O6: =PHLY!O6 -> 0 | ... AM6: =PHLY!AM6 -> 995 | AO6: =WANG!H6+PUNA!H6+GELA!H6+ZEMG!H6+TRON!H6+BUMA!H6+SARA!H6+TSIR!H6+DGNA!H6+PANG!H6+DPLA!H6+SJKA!H6+LUNT!H6+SAMC!H6+PHUA!H6+SAMA!H6+GMTU!H6+PHLY!AO6 -> 0 | AP6: =WANG!I6+PUNA!I6+GELA!I6+ZEMG!I6+TRON!I6+BUMA!I6+SARA!I6+TSIR!I6+DGNA!I6+PANG!I6+DPLA!I6+SJKA!I6+LUNT!I6+SAMC!I6+PHUA!I6+SAMA!I6+GMTU!I6+PHLY!AP6 -> 0 | AQ6: =WANG!J6+PUNA!J6+GELA!J6+ZEMG!J6+TRON!J6+BUMA!J6+SARA!J6+TSIR!J6+DGNA!J6+PANG!J6+DPLA!J6+SJKA!J6+LUNT!J6+SAMC!J6+PHUA!J6+SAMA!J6+GMTU!J6+PHLY!AQ6 -> 0 | AR6: =WANG!K6+PUNA!K6+GELA!K6+ZEMG!K6+TRON!K6+BUMA!K6+SARA!K6+TSIR!K6+DGNA!K6+PANG!K6+DPLA!K6+SJKA!K6+LUNT!K6+SAMC!K6+PHUA!K6+SAMA!K6+GMTU!K6+PHLY!AR6 -> 0 | AS6: =WANG!L6+PUNA!L6+GELA!L6+ZEMG!L6+TRON!L6+BUMA!L6+SARA!L6+TSIR!L6+DGNA!L6+PANG!L6+DPLA!L6+SJKA!L6+LUNT!L6+SAMC!L6+PHUA!L6+SAMA!L6+GMTU!L6+PHLY!AS6 -> 1 | AT6: =WANG!M6+PUNA!M6+GELA!M6+ZEMG!M6+TRON!M6+BUMA!M6+SARA!M6+TSIR!M6+DGNA!M6+PANG!M6+DPLA!M6+SJKA!M6+LUNT!M6+SAMC!M6+PHUA!M6+SAMA!M6+GMTU!M6+PHLY!AT6 -> 0 | AU6: =WANG!N6+PUNA!N6+GELA!N6+ZEMG!N6+TRON!N6+BUMA!N6+SARA!N6+TSIR!N6+DGNA!N6+PANG!N6+DPLA!N6+SJKA!N6+LUNT!N6+SAMC!N6+PHUA!N6+SAMA!N6+GMTU!N6+PHLY!AU6 -> 0 | AV6: =WANG!O6+PUNA!O6+GELA!O6+ZEMG!O6+TRON!O6+BUMA!O6+SARA!O6+TSIR!O6+DGNA!O6+PANG!O6+DPLA!O6+SJKA!O6+LUNT!O6+SAMC!O6+PHUA!O6+SAMA!O6+GMTU!O6+PHLY!AV6 -> 0 | ... BW6: =WANG!AP6+PUNA!AP6+GELA!AP6+ZEMG!AP6+TRON!AP6+BUMA!AP6+SARA!AP6+TSIR!AP6+DGNA!AP6+PANG!AP6+DPLA!AP6+SJKA!AP6+LUNT!AP6+SAMC!AP6+PHUA!AP6+SAMA!AP6+GMTU!AP6+PHLY!BW6 -> 14925 | BY6: =HAA!H6+WANG!AR6+PUNA!AR6+GASA!H6+GELA!AR6+ZEMG!AR6+TRON!AR6+BUMA!AR6+SARA!AR6+TSIR!AR6+DGNA!AR6+PANG!AR6+DPLA!AR6+SJKA!AR6+TRAG!H6+LUNT!AR6+WRMG!H6+NGLM!H6+SAMC!AR6+PHUA!AR6+GEDU!H6+SAMA!AR6+TCHG!H6+GMTU!AR6+PHLY!BY6 -> 0 | BZ6: =HAA!I6+WANG!AS6+PUNA!AS6+GASA!I6+GELA!AS6+ZEMG!AS6+TRON!AS6+BUMA!AS6+SARA!AS6+TSIR!AS6+DGNA!AS6+PANG!AS6+DPLA!AS6+SJKA!AS6+TRAG!I6+LUNT!AS6+WRMG!I6+NGLM!I6+SAMC!AS6+PHUA!AS6+GEDU!I6+SAMA!AS6+TCHG!I6+GMTU!AS6+PHLY!BZ6 -> 1 | CA6: =HAA!J6+WANG!AT6+PUNA!AT6+GASA!J6+GELA!AT6+ZEMG!AT6+TRON!AT6+BUMA!AT6+SARA!AT6+TSIR!AT6+DGNA!AT6+PANG!AT6+DPLA!AT6+SJKA!AT6+TRAG!J6+LUNT!AT6+WRMG!J6+NGLM!J6+SAMC!AT6+PHUA!AT6+GEDU!J6+SAMA!AT6+TCHG!J6+GMTU!AT6+PHLY!CA6 -> 2 | CB6: =HAA!K6+WANG!AU6+PUNA!AU6+GASA!K6+GELA!AU6+ZEMG!AU6+TRON!AU6+BUMA!AU6+SARA!AU6+TSIR!AU6+DGNA!AU6+PANG!AU6+DPLA!AU6+SJKA!AU6+TRAG!K6+LUNT!AU6+WRMG!K6+NGLM!K6+SAMC!AU6+PHUA!AU6+GEDU!K6+SAMA!AU6+TCHG!K6+GMTU!AU6+PHLY!CB6 -> 0 | CC6: =HAA!L6+WANG!AV6+PUNA!AV6+GASA!L6+GELA!AV6+ZEMG!AV6+TRON!AV6+BUMA!AV6+SARA!AV6+TSIR!AV6+DGNA!AV6+PANG!AV6+DPLA!AV6+SJKA!AV6+TRAG!L6+LUNT!AV6+WRMG!L6+NGLM!L6+SAMC!AV6+PHUA!AV6+GEDU!L6+SAMA!AV6+TCHG!L6+GMTU!AV6+PHLY!CC6 -> 0 | CD6: =HAA!M6+WANG!AW6+PUNA!AW6+GASA!M6+GELA!AW6+ZEMG!AW6+TRON!AW6+BUMA!AW6+SARA!AW6+TSIR!AW6+DGNA!AW6+PANG!AW6+DPLA!AW6+SJKA!AW6+TRAG!M6+LUNT!AW6+WRMG!M6+NGLM!M6+SAMC!AW6+PHUA!AW6+GEDU!M6+SAMA!AW6+TCHG!M6+GMTU!AW6+PHLY!CD6 -> 0 | CE6: =HAA!N6+WANG!AX6+PUNA!AX6+GASA!N6+GELA!AX6+ZEMG!AX6+TRON!AX6+BUMA!AX6+SARA!AX6+TSIR!AX6+DGNA!AX6+PANG!AX6+DPLA!AX6+SJKA!AX6+TRAG!N6+LUNT!AX6+WRMG!N6+NGLM!N6+SAMC!AX6+PHUA!AX6+GEDU!N6+SAMA!AX6+TCHG!N6+GMTU!AX6+PHLY!CE6 -> 0 | CF6: =HAA!O6+WANG!AY6+PUNA!AY6+GASA!O6+GELA!AY6+ZEMG!AY6+TRON!AY6+BUMA!AY6+SARA!AY6+TSIR!AY6+DGNA!AY6+PANG!AY6+DPLA!AY6+SJKA!AY6+TRAG!O6+LUNT!AY6+WRMG!O6+NGLM!O6+SAMC!AY6+PHUA!AY6+GEDU!O6+SAMA!AY6+TCHG!O6+GMTU!AY6+PHLY!CF6 -> 0 | ... DF6: =HAA!AO6+WANG!BY6+PUNA!BY6+GASA!AO6+GELA!BY6+ZEMG!BY6+TRON!BY6+BUMA!BY6+SARA!BY6+TSIR!BY6+DGNA!BY6+PANG!BY6+DPLA!BY6+SJKA!BY6+TRAG!AO6+LUNT!BY6+WRMG!AO6+NGLM!AO6+SAMC!BY6+PHUA!BY6+GEDU!AO6+SAMA!BY6+TCHG!AO6+GMTU!BY6+PHLY!DF6 -> 30845 | DG6: =AJ6+BT6+DC6 -> 47 | DH6: =C6*DG6 -> 46765 | DI6: =D6*DG6 -> 56118 | DJ6: =E6*DG6 -> 9353 | DN6: =PARO!H6+HAA!AQ6+WANG!CA6+PUNA!CA6+GASA!AQ6+GELA!CA6+ZEMG!CA6+TRON!CA6+BUMA!CA6+SARA!CA6+TSIR!CA6+DGNA!CA6+PANG!CA6+DPLA!CA6+SJKA!CA6+TRAG!AQ6+MONA!H6+LUNT!CA6+TYSE!H6+PEMA!H6+KNLG!H6+RJNG!H6+WRMG!AQ6+DUSM!H6+GYPG!H6+NGLM!AQ6+SAMC!CA6+PHUA!CA6+TSMA!H6+GEDU!AQ6+SAMA!CA6+TCHG!AQ6+GMTU!CA6+LHAM!H6+PHLY!DH6 -> 0 | DO6: =PARO!I6+HAA!AR6+WANG!CB6+PUNA!CB6+GASA!AR6+GELA!CB6+ZEMG!CB6+TRON!CB6+BUMA!CB6+SARA!CB6+TSIR!CB6+DGNA!CB6+PANG!CB6+DPLA!CB6+SJKA!CB6+TRAG!AR6+MONA!I6+LUNT!CB6+TYSE!I6+PEMA!I6+KNLG!I6+RJNG!I6+WRMG!AR6+DUSM!I6+GYPG!I6+NGLM!AR6+SAMC!CB6+PHUA!CB6+TSMA!I6+GEDU!AR6+SAMA!CB6+TCHG!AR6+GMTU!CB6+LHAM!I6+PHLY!DI6 -> 0 | DP6: =PARO!J6+HAA!AS6+WANG!CC6+PUNA!CC6+GASA!AS6+GELA!CC6+ZEMG!CC6+TRON!CC6+BUMA!CC6+SARA!CC6+TSIR!CC6+DGNA!CC6+PANG!CC6+DPLA!CC6+SJKA!CC6+TRAG!AS6+MONA!J6+LUNT!CC6+TYSE!J6+PEMA!J6+KNLG!J6+RJNG!J6+WRMG!AS6+DUSM!J6+GYPG!J6+NGLM!AS6+SAMC!CC6+PHUA!CC6+TSMA!J6+GEDU!AS6+SAMA!CC6+TCHG!AS6+GMTU!CC6+LHAM!J6+PHLY!DJ6 -> 0 | DQ6: =PARO!K6+HAA!AT6+WANG!CD6+PUNA!CD6+GASA!AT6+GELA!CD6+ZEMG!CD6+TRON!CD6+BUMA!CD6+SARA!CD6+TSIR!CD6+DGNA!CD6+PANG!CD6+DPLA!CD6+SJKA!CD6+TRAG!AT6+MONA!K6+LUNT!CD6+TYSE!K6+PEMA!K6+KNLG!K6+RJNG!K6+WRMG!AT6+DUSM!K6+GYPG!K6+NGLM!AT6+SAMC!CD6+PHUA!CD6+TSMA!K6+GEDU!AT6+SAMA!CD6+TCHG!AT6+GMTU!CD6+LHAM!K6+PHLY!DK6 -> 0 | DR6: =PARO!L6+HAA!AU6+WANG!CE6+PUNA!CE6+GASA!AU6+GELA!CE6+ZEMG!CE6+TRON!CE6+BUMA!CE6+SARA!CE6+TSIR!CE6+DGNA!CE6+PANG!CE6+DPLA!CE6+SJKA!CE6+TRAG!AU6+MONA!L6+LUNT!CE6+TYSE!L6+PEMA!L6+KNLG!L6+RJNG!L6+WRMG!AU6+DUSM!L6+GYPG!L6+NGLM!AU6+SAMC!CE6+PHUA!CE6+TSMA!L6+GEDU!AU6+SAMA!CE6+TCHG!AU6+GMTU!CE6+LHAM!L6+PHLY!DL6 -> 2 | DS6: =PARO!M6+HAA!AV6+WANG!CF6+PUNA!CF6+GASA!AV6+GELA!CF6+ZEMG!CF6+TRON!CF6+BUMA!CF6+SARA!CF6+TSIR!CF6+DGNA!CF6+PANG!CF6+DPLA!CF6+SJKA!CF6+TRAG!AV6+MONA!M6+LUNT!CF6+TYSE!M6+PEMA!M6+KNLG!M6+RJNG!M6+WRMG!AV6+DUSM!M6+GYPG!M6+NGLM!AV6+SAMC!CF6+PHUA!CF6+TSMA!M6+GEDU!AV6+SAMA!CF6+TCHG!AV6+GMTU!CF6+LHAM!M6+PHLY!DM6 -> 3 | DT6: =PARO!N6+HAA!AW6+WANG!CG6+PUNA!CG6+GASA!AW6+GELA!CG6+ZEMG!CG6+TRON!CG6+BUMA!CG6+SARA!CG6+TSIR!CG6+DGNA!CG6+PANG!CG6+DPLA!CG6+SJKA!CG6+TRAG!AW6+MONA!N6+LUNT!CG6+TYSE!N6+PEMA!N6+KNLG!N6+RJNG!N6+WRMG!AW6+DUSM!N6+GYPG!N6+NGLM!AW6+SAMC!CG6+PHUA!CG6+TSMA!N6+GEDU!AW6+SAMA!CG6+TCHG!AW6+GMTU!CG6+LHAM!N6+PHLY!DN6 -> 0 | DU6: =PARO!O6+HAA!AX6+WANG!CH6+PUNA!CH6+GASA!AX6+GELA!CH6+ZEMG!CH6+TRON!CH6+BUMA!CH6+SARA!CH6+TSIR!CH6+DGNA!CH6+PANG!CH6+DPLA!CH6+SJKA!CH6+TRAG!AX6+MONA!O6+LUNT!CH6+TYSE!O6+PEMA!O6+KNLG!O6+RJNG!O6+WRMG!AX6+DUSM!O6+GYPG!O6+NGLM!AX6+SAMC!CH6+PHUA!CH6+TSMA!O6+GEDU!AX6+SAMA!CH6+TCHG!AX6+GMTU!CH6+LHAM!O6+PHLY!DO6 -> 6 | ... EV6: =PARO!AP6+HAA!BY6+WANG!DI6+PUNA!DI6+GASA!BY6+GELA!DI6+ZEMG!DI6+TRON!DI6+BUMA!DI6+SARA!DI6+TSIR!DI6+DGNA!DI6+PANG!DI6+DPLA!DI6+SJKA!DI6+TRAG!BY6+MONA!AP6+LUNT!DI6+TYSE!AP6+PEMA!AP6+KNLG!AP6+RJNG!AP6+WRMG!BY6+DUSM!AP6+GYPG!AP6+NGLM!BY6+SAMC!DI6+PHUA!DI6+TSMA!AP6+GEDU!BY6+SAMA!DI6+TCHG!BY6+GMTU!DI6+LHAM!AP6+PHLY!EP6 -> 21890 | EX6: =PARO!AR6+HAA!CA6+WANG!DK6+PUNA!DK6+GASA!CA6+GELA!DK6+ZEMG!DK6+TRON!DK6+BUMA!DK6+SARA!DK6+TSIR!DK6+DGNA!DK6+PANG!DK6+DPLA!DK6+SJKA!DK6+TRAG!CA6+MONA!AR6+LUNT!DK6+TYSE!AR6+PEMA!AR6+KNLG!AR6+RJNG!AR6+WRMG!CA6+DUSM!AR6+GYPG!AR6+NGLM!CA6+SAMC!DK6+PHUA!DK6+TSMA!AR6+GEDU!CA6+SAMA!DK6+TCHG!CA6+GMTU!DK6+LHAM!AR6+PHLY!ER6 -> 0 | EY6: =PARO!AS6+HAA!CB6+WANG!DL6+PUNA!DL6+GASA!CB6+GELA!DL6+ZEMG!DL6+TRON!DL6+BUMA!DL6+SARA!DL6+TSIR!DL6+DGNA!DL6+PANG!DL6+DPLA!DL6+SJKA!DL6+TRAG!CB6+MONA!AS6+LUNT!DL6+TYSE!AS6+PEMA!AS6+KNLG!AS6+RJNG!AS6+WRMG!CB6+DUSM!AS6+GYPG!AS6+NGLM!CB6+SAMC!DL6+PHUA!DL6+TSMA!AS6+GEDU!CB6+SAMA!DL6+TCHG!CB6+GMTU!DL6+LHAM!AS6+PHLY!ES6 -> 0 | EZ6: =PARO!AT6+HAA!CC6+WANG!DM6+PUNA!DM6+GASA!CC6+GELA!DM6+ZEMG!DM6+TRON!DM6+BUMA!DM6+SARA!DM6+TSIR!DM6+DGNA!DM6+PANG!DM6+DPLA!DM6+SJKA!DM6+TRAG!CC6+MONA!AT6+LUNT!DM6+TYSE!AT6+PEMA!AT6+KNLG!AT6+RJNG!AT6+WRMG!CC6+DUSM!AT6+GYPG!AT6+NGLM!CC6+SAMC!DM6+PHUA!DM6+TSMA!AT6+GEDU!CC6+SAMA!DM6+TCHG!CC6+GMTU!DM6+LHAM!AT6+PHLY!ET6 -> 0 | FA6: =PARO!AU6+HAA!CD6+WANG!DN6+PUNA!DN6+GASA!CD6+GELA!DN6+ZEMG!DN6+TRON!DN6+BUMA!DN6+SARA!DN6+TSIR!DN6+DGNA!DN6+PANG!DN6+DPLA!DN6+SJKA!DN6+TRAG!CD6+MONA!AU6+LUNT!DN6+TYSE!AU6+PEMA!AU6+KNLG!AU6+RJNG!AU6+WRMG!CD6+DUSM!AU6+GYPG!AU6+NGLM!CD6+SAMC!DN6+PHUA!DN6+TSMA!AU6+GEDU!CD6+SAMA!DN6+TCHG!CD6+GMTU!DN6+LHAM!AU6+PHLY!EU6 -> 0 | FB6: =PARO!AV6+HAA!CE6+WANG!DO6+PUNA!DO6+GASA!CE6+GELA!DO6+ZEMG!DO6+TRON!DO6+BUMA!DO6+SARA!DO6+TSIR!DO6+DGNA!DO6+PANG!DO6+DPLA!DO6+SJKA!DO6+TRAG!CE6+MONA!AV6+LUNT!DO6+TYSE!AV6+PEMA!AV6+KNLG!AV6+RJNG!AV6+WRMG!CE6+DUSM!AV6+GYPG!AV6+NGLM!CE6+SAMC!DO6+PHUA!DO6+TSMA!AV6+GEDU!CE6+SAMA!DO6+TCHG!CE6+GMTU!DO6+LHAM!AV6+PHLY!EV6 -> 0 | FC6: =PARO!AW6+HAA!CF6+WANG!DP6+PUNA!DP6+GASA!CF6+GELA!DP6+ZEMG!DP6+TRON!DP6+BUMA!DP6+SARA!DP6+TSIR!DP6+DGNA!DP6+PANG!DP6+DPLA!DP6+SJKA!DP6+TRAG!CF6+MONA!AW6+LUNT!DP6+TYSE!AW6+PEMA!AW6+KNLG!AW6+RJNG!AW6+WRMG!CF6+DUSM!AW6+GYPG!AW6+NGLM!CF6+SAMC!DP6+PHUA!DP6+TSMA!AW6+GEDU!CF6+SAMA!DP6+TCHG!CF6+GMTU!DP6+LHAM!AW6+PHLY!EW6 -> 0 | FD6: =PARO!AX6+HAA!CG6+WANG!DQ6+PUNA!DQ6+GASA!CG6+GELA!DQ6+ZEMG!DQ6+TRON!DQ6+BUMA!DQ6+SARA!DQ6+TSIR!DQ6+DGNA!DQ6+PANG!DQ6+DPLA!DQ6+SJKA!DQ6+TRAG!CG6+MONA!AX6+LUNT!DQ6+TYSE!AX6+PEMA!AX6+KNLG!AX6+RJNG!AX6+WRMG!CG6+DUSM!AX6+GYPG!AX6+NGLM!CG6+SAMC!DQ6+PHUA!DQ6+TSMA!AX6+GEDU!CG6+SAMA!DQ6+TCHG!CG6+GMTU!DQ6+LHAM!AX6+PHLY!EX6 -> 5 | FE6: =PARO!AY6+HAA!CH6+WANG!DR6+PUNA!DR6+GASA!CH6+GELA!DR6+ZEMG!DR6+TRON!DR6+BUMA!DR6+SARA!DR6+TSIR!DR6+DGNA!DR6+PANG!DR6+DPLA!DR6+SJKA!DR6+TRAG!CH6+MONA!AY6+LUNT!DR6+TYSE!AY6+PEMA!AY6+KNLG!AY6+RJNG!AY6+WRMG!CH6+DUSM!AY6+GYPG!AY6+NGLM!CH6+SAMC!DR6+PHUA!DR6+TSMA!AY6+GEDU!CH6+SAMA!DR6+TCHG!CH6+GMTU!DR6+LHAM!AY6+PHLY!EY6 -> 0 | ... GA6: =PARO!BU6+HAA!DD6+WANG!EN6+PUNA!EN6+GASA!DD6+GELA!EN6+ZEMG!EN6+TRON!EN6+BUMA!EN6+SARA!EN6+TSIR!EN6+DGNA!EN6+PANG!EN6+DPLA!EN6+SJKA!EN6+TRAG!DD6+MONA!BU6+LUNT!EN6+TYSE!BU6+PEMA!BU6+KNLG!BU6+RJNG!BU6+WRMG!DD6+DUSM!BU6+GYPG!BU6+NGLM!DD6+SAMC!EN6+PHUA!EN6+TSMA!BU6+GEDU!DD6+SAMA!EN6+TCHG!DD6+GMTU!EN6+LHAM!BU6+PHLY!FU6 -> 0 | GB6: =PARO!BV6+HAA!DE6+WANG!EO6+PUNA!EO6+GASA!DE6+GELA!EO6+ZEMG!EO6+TRON!EO6+BUMA!EO6+SARA!EO6+TSIR!EO6+DGNA!EO6+PANG!EO6+DPLA!EO6+SJKA!EO6+TRAG!DE6+MONA!BW6+LUNT!EO6+TYSE!BW6+PEMA!BW6+KNLG!BW6+RJNG!BV6+WRMG!DE6+DUSM!BW6+GYPG!BW6+NGLM!DE6+SAMC!EO6+PHUA!EO6+TSMA!BV6+GEDU!DE6+SAMA!EO6+TCHG!DE6+GMTU!EO6+LHAM!BV6+PHLY!FV6 -> 13 | GC6: =PARO!BW6+HAA!DF6+WANG!EP6+PUNA!EP6+GASA!DF6+GELA!EP6+ZEMG!EP6+TRON!EP6+BUMA!EP6+SARA!EP6+TSIR!EP6+DGNA!EP6+PANG!EP6+DPLA!EP6+SJKA!EP6+TRAG!DF6+MONA!BX6+LUNT!EP6+TYSE!BX6+PEMA!BX6+KNLG!BX6+RJNG!BW6+WRMG!DF6+DUSM!BX6+GYPG!BX6+NGLM!DF6+SAMC!EP6+PHUA!EP6+TSMA!BW6+GEDU!DF6+SAMA!EP6+TCHG!DF6+GMTU!EP6+LHAM!BW6+PHLY!FW6 -> 15522 | GD6: =PARO!BX6+HAA!DG6+WANG!EQ6+PUNA!EQ6+GASA!DG6+GELA!EQ6+ZEMG!EQ6+TRON!EQ6+BUMA!EQ6+SARA!EQ6+TSIR!EQ6+DGNA!EQ6+PANG!EQ6+DPLA!EQ6+SJKA!EQ6+TRAG!DG6+MONA!BY6+LUNT!EQ6+TYSE!BY6+PEMA!BY6+KNLG!BY6+RJNG!BX6+WRMG!DG6+DUSM!BY6+GYPG!BY6+NGLM!DG6+SAMC!EQ6+PHUA!EQ6+TSMA!BX6+GEDU!DG6+SAMA!EQ6+TCHG!DG6+GMTU!EQ6+LHAM!BX6+PHLY!FX6 -> 2587 | GE6: =PARO!BY6+HAA!DH6+WANG!ER6+PUNA!ER6+GASA!DH6+GELA!ER6+ZEMG!ER6+TRON!ER6+BUMA!ER6+SARA!ER6+TSIR!ER6+DGNA!ER6+PANG!ER6+DPLA!ER6+SJKA!ER6+TRAG!DH6+MONA!BZ6+LUNT!ER6+TYSE!BZ6+PEMA!BZ6+KNLG!BZ6+RJNG!BY6+WRMG!DH6+DUSM!BZ6+GYPG!BZ6+NGLM!DH6+SAMC!ER6+PHUA!ER6+TSMA!BY6+GEDU!DH6+SAMA!ER6+TCHG!DH6+GMTU!ER6+LHAM!BY6+PHLY!FY6 -> 12935 | GG6: =PARO!CA6+HAA!DJ6+WANG!ET6+PUNA!ET6+GASA!DJ6+GELA!ET6+ZEMG!ET6+TRON!ET6+BUMA!ET6+SARA!ET6+TSIR!ET6+DGNA!ET6+PANG!ET6+DPLA!ET6+SJKA!ET6+TRAG!DJ6+MONA!CB6+LUNT!ET6+TYSE!CB6+PEMA!CB6+KNLG!CB6+RJNG!CA6+WRMG!DJ6+DUSM!CB6+GYPG!CB6+NGLM!DJ6+SAMC!ET6+PHUA!ET6+TSMA!CA6+GEDU!DJ6+SAMA!ET6+TCHG!DJ6+GMTU!ET6+LHAM!CA6+PHLY!GA6 -> 0 | GH6: =PARO!CB6+HAA!DK6+WANG!EU6+PUNA!EU6+GASA!DK6+GELA!EU6+ZEMG!EU6+TRON!EU6+BUMA!EU6+SARA!EU6+TSIR!EU6+DGNA!EU6+PANG!EU6+DPLA!EU6+SJKA!EU6+TRAG!DK6+MONA!CC6+LUNT!EU6+TYSE!CC6+PEMA!CC6+KNLG!CC6+RJNG!CB6+WRMG!DK6+DUSM!CC6+GYPG!CC6+NGLM!DK6+SAMC!EU6+PHUA!EU6+TSMA!CB6+GEDU!DK6+SAMA!EU6+TCHG!DK6+GMTU!EU6+LHAM!CB6+PHLY!GB6 -> 2 | GI6: =PARO!CC6+HAA!DL6+WANG!EV6+PUNA!EV6+GASA!DL6+GELA!EV6+ZEMG!EV6+TRON!EV6+BUMA!EV6+SARA!EV6+TSIR!EV6+DGNA!EV6+PANG!EV6+DPLA!EV6+SJKA!EV6+TRAG!DL6+MONA!CD6+LUNT!EV6+TYSE!CD6+PEMA!CD6+KNLG!CD6+RJNG!CC6+WRMG!DL6+DUSM!CD6+GYPG!CD6+NGLM!DL6+SAMC!EV6+PHUA!EV6+TSMA!CC6+GEDU!DL6+SAMA!EV6+TCHG!DL6+GMTU!EV6+LHAM!CC6+PHLY!GC6 -> 0 | GJ6: =PARO!CD6+HAA!DM6+WANG!EW6+PUNA!EW6+GASA!DM6+GELA!EW6+ZEMG!EW6+TRON!EW6+BUMA!EW6+SARA!EW6+TSIR!EW6+DGNA!EW6+PANG!EW6+DPLA!EW6+SJKA!EW6+TRAG!DM6+MONA!CE6+LUNT!EW6+TYSE!CE6+PEMA!CE6+KNLG!CE6+RJNG!CD6+WRMG!DM6+DUSM!CE6+GYPG!CE6+NGLM!DM6+SAMC!EW6+PHUA!EW6+TSMA!CD6+GEDU!DM6+SAMA!EW6+TCHG!DM6+GMTU!EW6+LHAM!CD6+PHLY!GD6 -> 1 | GK6: =PARO!CE6+HAA!DN6+WANG!EX6+PUNA!EX6+GASA!DN6+GELA!EX6+ZEMG!EX6+TRON!EX6+BUMA!EX6+SARA!EX6+TSIR!EX6+DGNA!EX6+PANG!EX6+DPLA!EX6+SJKA!EX6+TRAG!DN6+MONA!CF6+LUNT!EX6+TYSE!CF6+PEMA!CF6+KNLG!CF6+RJNG!CE6+WRMG!DN6+DUSM!CF6+GYPG!CF6+NGLM!DN6+SAMC!EX6+PHUA!EX6+TSMA!CE6+GEDU!DN6+SAMA!EX6+TCHG!DN6+GMTU!EX6+LHAM!CE6+PHLY!GE6 -> 0 | GL6: =PARO!CF6+HAA!DO6+WANG!EY6+PUNA!EY6+GASA!DO6+GELA!EY6+ZEMG!EY6+TRON!EY6+BUMA!EY6+SARA!EY6+TSIR!EY6+DGNA!EY6+PANG!EY6+DPLA!EY6+SJKA!EY6+TRAG!DO6+MONA!CG6+LUNT!EY6+TYSE!CG6+PEMA!CG6+KNLG!CG6+RJNG!CF6+WRMG!DO6+DUSM!CG6+GYPG!CG6+NGLM!DO6+SAMC!EY6+PHUA!EY6+TSMA!CF6+GEDU!DO6+SAMA!EY6+TCHG!DO6+GMTU!EY6+LHAM!CF6+PHLY!GF6 -> 0 | GM6: =PARO!CG6+HAA!DP6+WANG!EZ6+PUNA!EZ6+GASA!DP6+GELA!EZ6+ZEMG!EZ6+TRON!EZ6+BUMA!EZ6+SARA!EZ6+TSIR!EZ6+DGNA!EZ6+PANG!EZ6+DPLA!EZ6+SJKA!EZ6+TRAG!DP6+MONA!CH6+LUNT!EZ6+TYSE!CH6+PEMA!CH6+KNLG!CH6+RJNG!CG6+WRMG!DP6+DUSM!CH6+GYPG!CH6+NGLM!DP6+SAMC!EZ6+PHUA!EZ6+TSMA!CG6+GEDU!DP6+SAMA!EZ6+TCHG!DP6+GMTU!EZ6+LHAM!CG6+PHLY!GG6 -> 0 | GN6: =PARO!CH6+HAA!DQ6+WANG!FA6+PUNA!FA6+GASA!DQ6+GELA!FA6+ZEMG!FA6+TRON!FA6+BUMA!FA6+SARA!FA6+TSIR!FA6+DGNA!FA6+PANG!FA6+DPLA!FA6+SJKA!FA6+TRAG!DQ6+MONA!CI6+LUNT!FA6+TYSE!CI6+PEMA!CI6+KNLG!CI6+RJNG!CH6+WRMG!DQ6+DUSM!CI6+GYPG!CI6+NGLM!DQ6+SAMC!FA6+PHUA!FA6+TSMA!CH6+GEDU!DQ6+SAMA!FA6+TCHG!DQ6+GMTU!FA6+LHAM!CH6+PHLY!GH6 -> 0 | ... HO6: =PARO!DI6+HAA!ER6+WANG!GB6+PUNA!GB6+GASA!ER6+GELA!GB6+ZEMG!GB6+TRON!GB6+BUMA!GB6+SARA!GB6+TSIR!GB6+DGNA!GB6+PANG!GB6+DPLA!GB6+SJKA!GB6+TRAG!ER6+MONA!DJ6+LUNT!GB6+TYSE!DJ6+PEMA!DJ6+KNLG!DJ6+RJNG!DI6+WRMG!ER6+DUSM!DJ6+GYPG!DJ6+NGLM!ER6+SAMC!GB6+PHUA!GB6+TSMA!DI6+GEDU!ER6+SAMA!GB6+TCHG!ER6+GMTU!GB6+LHAM!DI6+PHLY!HI6 -> 3980 | HQ6: =ES6+GB6+HL6 -> 39 | HR6: =C6*HQ6 -> 38805 | HS6: =D6*HQ6 -> 46566 | HT6: =E6*HQ6 -> 7761 | IN6: =AJ6+BT6+DC6+ES6+GB6+HL6 -> 86 | IO6: =AK6+BU6+DD6+ET6+GC6+HM6 -> 102684 | IP6: =AL6+BV6+DE6+EU6+GD6+HN6 -> 17114 | IQ6: =AM6+BW6+DF6+EV6+GE6+HO6 -> 85570
